Workbook

Sheet No Lens
A2: Color Source Strip Deep Blue | B2: 42541
B4: Beam Angle | C4: Field Angle
B5: 15.3 | C5: 27.2
F6: Lens Efficiency | G6: Power Consump (Watts) | H6: Efficacy (lm/W)
A7: Setting/Mode | B7: Accessory Lens | C7: Candela | D7: Field Lumens | E7: Beam Lumens
A8: Full / RGB | B8: none | C8: 31917 | D8: 2141 | E8: 1173 | F8: NA | G8: 71.8 | H8: =D8/G8 -> 29.818942
A9: Full / Direct | B9: none | C9: 36097 | D9: 2429 | E9: 1329 | F9: NA | G9: 101.7 | H9: =D9/G9 -> 23.883972
A10: 3200K / RGB | B10: none | C10: 35356 | D10: 2366 | E10: 1296 | F10: NA | G10: 77.5 | H10: =D10/G10 -> 30.529032
A11: 5600K / RGB | B11: none | C11: 31760 | D11: 2126 | E11: 1165 | F11: NA | G11: 71.6 | H11: =D11/G11 -> 29.692737
A12: Red / RGB | B12: none | C12: 8221 | D12: 566 | E12: 308 | F12: NA | G12: 27.5 | H12: =D12/G12 -> 20.581818
A13: Green / RGB | B13: none | C13: 11022 | D13: 675 | E13: 354 | F13: NA | G13: 30.3 | H13: =D13/G13 -> 22.277228
A14: Blue / RGB | B14: none | C14: 1152 | D14: 81 | E14: 44 | F14: NA | G14: 31.2 | H14: =D14/G14 -> 2.5961538
B16: For Field diameter at any distance, multiply distance by | F16: =2*TAN(C5*3.1415926535/360) -> 0.48385092
B18: For Beam diameter at any distance, multiply distance by | F18: =2*TAN(B5*3.1415926535/360) -> 0.26863358
G19: Dist for 1.0 fc
B20: Throw Distance (ft) | C20: 10 | D20: 15 | E20: 20 | F20: 25 | G20: =SQRT(C8) -> 178.6533
B21: Throw Distance (m) | C21: =C20*0.3048 -> 3.048 | D21: =D20*0.3048 -> 4.572 | E21: =E20*0.3048 -> 6.096 | F21: =F20*0.3048 -> 7.62 | G21: =G20*0.3048 -> 54.453524
B22: Field Diameter (ft) | C22: =C20*F16 -> 4.8385092 | D22: =D20*F16 -> 7.2577638 | E22: =E20*F16 -> 9.6770184 | F22: =F20*F16 -> 12.096273
B23: Field Diameter (m) | C23: =C21*F16 -> 1.4747776 | D23: =D21*F16 -> 2.2121664 | E23: =E21*F16 -> 2.9495552 | F23: =F21*F16 -> 3.686944
B24: Illuminance (fc) | C24: =C8/(C20*C20) -> 319.17 | D24: =C8/(D20*D20) -> 141.85333 | E24: =C8/(E20*E20) -> 79.7925 | F24: =C8/(F20*F20) -> 51.0672
B25: Illuminance (lux) | C25: =C24*10.7639 -> 3435.514 | D25: =D24*10.7639 -> 1526.8951 | E25: =E24*10.7639 -> 858.87849 | F25: =F24*10.7639 -> 549.68223
A27: Test Distance | B27: Iso-Illuminance Diagram grid lines
A28: 147.25 | B28: 12.5 | C28: 25 | D28: 37.5 | E28: 50
B29: =B28/A28 -> 0.084889643 | C29: =C28/A28 -> 0.16977929 | D29: =D28/A28 -> 0.25466893 | E29: =E28/A28 -> 0.33955857
A56: Measurement: Full ON RGB - Intensity
A58: Degrees | B58: (Cd)
A59: -21.77432 | B59: 0
A60: -21.72434 | B60: 0
A61: -21.67435 | B61: 0
A62: -21.62437 | B62: 0
A63: -21.57439 | B63: 0
A64: -21.5244 | B64: 0
A65: -21.47442 | B65: 0
A66: -21.42443 | B66: 0
A67: -21.37445 | B67: 0
A68: -21.32446 | B68: 0
A69: -21.27448 | B69: 0
A70: -21.2245 | B70: 0
... A930: 21.76183 | B930: 683.9916
A932: Degrees | B932: (Cd)
...

Sheet VNR
A2: Color Source Strip Deep Blue | B2: 42541
B4: Beam Angle | C4: Field Angle
B5: 15.5 | C5: 27.6
F6: Lens Efficiency | G6: Power Consump (Watts) | H6: Efficacy (lm/W)
A7: Mode | B7: Accessory Lens | C7: Candela | D7: Field Lumens | E7: Beam Lumens
A8: RGB - full | B8: VNR | C8: 25336 | D8: 1964 | E8: 1004 | F8: =D8/'No Lens'!D8 -> 0.91732835 | G8: 71.8 | H8: =D8/G8 -> 27.35376
A9: Max output | B9: VNR | C9: =1.13274*C8 -> 28699.101 | D9: =1.13274*D8 -> 2224.7014 | E9: =1.13274*E8 -> 1137.271 | F9: =F8 -> 0.91732835 | G9: 101.7 | H9: =D9/G9 -> 21.875136
A10: 3200K | B10: VNR | C10: =1.10642*C8 -> 28032.257 | D10: =1.10642*D8 -> 2173.0089 | E10: =1.10642*E8 -> 1110.8457 | F10: =F8 -> 0.91732835 | G10: 77.5 | H10: =D10/G10 -> 28.038824
A11: 5600K | B11: VNR | C11: =0.99404*C8 -> 25184.997 | D11: =0.99404*D8 -> 1952.2946 | E11: =0.99404*E8 -> 998.01616 | F11: =F8 -> 0.91732835 | G11: 71.6 | H11: =D11/G11 -> 27.266684
A12: Red | B12: VNR | C12: =0.26097*C8 -> 6611.9359 | D12: =0.26097*D8 -> 512.54508 | E12: =0.26097*E8 -> 262.01388 | F12: =F8 -> 0.91732835 | G12: 27.5 | H12: =D12/G12 -> 18.638003
A13: Green | B13: VNR | C13: =0.3303*C8 -> 8368.4808 | D13: =0.3303*D8 -> 648.7092 | E13: =0.3303*E8 -> 331.6212 | F13: =F8 -> 0.91732835 | G13: 30.3 | H13: =D13/G13 -> 21.409545
A14: Blue | B14: VNR | C14: =0.03696*C8 -> 936.41856 | D14: =0.03696*D8 -> 72.58944 | E14: =0.03696*E8 -> 37.10784 | F14: =F8 -> 0.91732835 | G14: 31.2 | H14: =D14/G14 -> 2.3265846
B16: For Field diameter at any distance, multiply distance by | F16: =2*TAN(C5*3.1415926535/360) -> 0.49124712
B18: For Beam diameter at any distance, multiply distance by | F18: =2*TAN(B5*3.1415926535/360) -> 0.27218805
G19: Dist for 1.0 fc
B20: Throw Distance (ft) | C20: 10 | D20: 15 | E20: 20 | F20: 25 | G20: =SQRT(C8) -> 159.17286
B21: Throw Distance (m) | C21: =C20*0.3048 -> 3.048 | D21: =D20*0.3048 -> 4.572 | E21: =E20*0.3048 -> 6.096 | F21: =F20*0.3048 -> 7.62 | G21: =G20*0.3048 -> 48.515888
B22: Field Diameter (ft) | C22: =C20*F16 -> 4.9124712 | D22: =D20*F16 -> 7.3687068 | E22: =E20*F16 -> 9.8249423 | F22: =F20*F16 -> 12.281178
B23: Field Diameter (m) | C23: =C21*F16 -> 1.4973212 | D23: =D21*F16 -> 2.2459818 | E23: =E21*F16 -> 2.9946424 | F23: =F21*F16 -> 3.743303
B24: Illuminance (fc) | C24: =C8/(C20*C20) -> 253.36 | D24: =C8/(D20*D20) -> 112.60444 | E24: =C8/(E20*E20) -> 63.34 | F24: =C8/(F20*F20) -> 40.5376
B25: Illuminance (lux) | C25: =C24*10.7639 -> 2727.1417 | D25: =D24*10.7639 -> 1212.063 | E25: =E24*10.7639 -> 681.78543 | F25: =F24*10.7639 -> 436.34267
A27: Test Distance | B27: Iso-Illuminance Diagram grid lines
A28: 147 | B28: 12.5 | C28: 25 | D28: 37.5 | E28: 50
B29: =B28/A28 -> 0.085034014 | C29: =C28/A28 -> 0.17006803 | D29: =D28/A28 -> 0.25510204 | E29: =E28/A28 -> 0.34013605
A56: Measurement: VNR Full ON RGB - Intensity
A58: Degrees | B58: (Cd)
A59: -21.80603 | B59: 0
A60: -21.75597 | B60: 0
A61: -21.70592 | B61: 0
A62: -21.65586 | B62: 0
A63: -21.6058 | B63: 0
A64: -21.55574 | B64: 0
A65: -21.50569 | B65: 0
A66: -21.45563 | B66: 0
A67: -21.40557 | B67: 0
A68: -21.35552 | B68: 0
A69: -21.30546 | B69: 0
A70: -21.2554 | B70: 0
... A930: 21.79351 | B930: 723.789
A932: Degrees | B932: (Cd)
...

Sheet VNL
A2: Color Source Strip Deep Blue | B2: 42541
B4: Beam Angle | C4: Field Angle
A5: Horizontal | B5: 29 | C5: 45.6
F6: Lens Efficiency | G6: Power Consump (Watts) | H6: Efficacy (lm/W)
A7: Mode | B7: Accessory Lens | C7: Candela | D7: Field Lumens | E7: Beam Lumens
A8: RGB - full | B8: VNL | C8: 16922 | D8: 2095 | E8: 1134 | F8: =D8/'No Lens'!D8 -> 0.97851471 | G8: 71.8 | H8: =D8/G8 -> 29.178273
A9: Max output | B9: VNL | C9: =1.13274*C8 -> 19168.226 | D9: =1.13274*D8 -> 2373.0903 | E9: =1.13274*E8 -> 1284.5272 | F9: =F8 -> 0.97851471 | G9: 101.7 | H9: =D9/G9 -> 23.334221
A10: 3200K | B10: VNL | C10: =1.10642*C8 -> 18722.839 | D10: =1.10642*D8 -> 2317.9499 | E10: =1.10642*E8 -> 1254.6803 | F10: =F8 -> 0.97851471 | G10: 77.5 | H10: =D10/G10 -> 29.909031
A11: 5600K | B11: VNL | C11: =0.99404*C8 -> 16821.145 | D11: =0.99404*D8 -> 2082.5138 | E11: =0.99404*E8 -> 1127.2414 | F11: =F8 -> 0.97851471 | G11: 71.6 | H11: =D11/G11 -> 29.085388
A12: Red | B12: VNL | C12: =0.26097*C8 -> 4416.1343 | D12: =0.26097*D8 -> 546.73215 | E12: =0.26097*E8 -> 295.93998 | F12: =F8 -> 0.97851471 | G12: 27.5 | H12: =D12/G12 -> 19.881169
A13: Green | B13: VNL | C13: =0.3303*C8 -> 5589.3366 | D13: =0.3303*D8 -> 691.9785 | E13: =0.3303*E8 -> 374.5602 | F13: =F8 -> 0.97851471 | G13: 30.3 | H13: =D13/G13 -> 22.837574
A14: Blue | B14: VNL | C14: =0.03696*C8 -> 625.43712 | D14: =0.03696*D8 -> 77.4312 | E14: =0.03696*E8 -> 41.91264 | F14: =F8 -> 0.97851471 | G14: 31.2 | H14: =D14/G14 -> 2.4817692
B16: For Field diameter at any distance, multiply distance by | F16: =2*TAN(C5*3.1415926535/360) -> 0.84072259
B18: For Beam diameter at any distance, multiply distance by | F18: =2*TAN(B5*3.1415926535/360) -> 0.51723517
G19: Dist for 1.0 fc
B20: Throw Distance (ft) | C20: 10 | D20: 15 | E20: 20 | F20: 25 | G20: =SQRT(C8) -> 130.08459
B21: Throw Distance (m) | C21: =C20*0.3048 -> 3.048 | D21: =D20*0.3048 -> 4.572 | E21: =E20*0.3048 -> 6.096 | F21: =F20*0.3048 -> 7.62 | G21: =G20*0.3048 -> 39.649782
B22: Field Diameter (ft) | C22: =C20*F16 -> 8.4072259 | D22: =D20*F16 -> 12.610839 | E22: =E20*F16 -> 16.814452 | F22: =F20*F16 -> 21.018065
B23: Field Diameter (m) | C23: =C21*F16 -> 2.5625224 | D23: =D21*F16 -> 3.8437837 | E23: =E21*F16 -> 5.1250449 | F23: =F21*F16 -> 6.4063061
B24: Illuminance (fc) | C24: =C8/(C20*C20) -> 169.22 | D24: =C8/(D20*D20) -> 75.208889 | E24: =C8/(E20*E20) -> 42.305 | F24: =C8/(F20*F20) -> 27.0752
B25: Illuminance (lux) | C25: =C24*10.7639 -> 1821.4672 | D25: =D24*10.7639 -> 809.54096 | E25: =E24*10.7639 -> 455.36679 | F25: =F24*10.7639 -> 291.43475
B27: Beam Angle | C27: Field Angle
A28: Vertical | B28: 14.4 | C28: 28.7
B30: For Field height at any distance, multiply distance by | F30: =2*TAN(C28*3.1415926535/360) -> 0.51165275
B32: For Beam height at any distance, multiply distance by | F32: =2*TAN(B28*3.1415926535/360) -> 0.25265876
A34: Test Distance | B34: Iso-Illuminance Diagram grid lines
A35: 92 | B35: 10 | C35: 20 | D35: 30 | E35: 40 | F35: 50
B36: =B35/A35 -> 0.10869565 | C36: =C35/A35 -> 0.2173913 | D36: =D35/A35 -> 0.32608696 | E36: =E35/A35 -> 0.43478261 | F36: =F35/A35 -> 0.54347826
A42: Measurement: 20H Full ON RGB - Intensity
A44: Degrees | B44: (Cd)
A45: -31.62508 | B45: 0
A46: -31.57517 | B46: 0
A47: -31.52526 | B47: 0
A48: -31.47535 | B48: 0
A49: -31.42544 | B49: 0
A50: -31.37553 | B50: 0
A51: -31.32562 | B51: 0
A52: -31.27571 | B52: 0
A53: -31.2258 | B53: 0
A54: -31.17589 | B54: 0
...

Sheet NR
A2: Color Source Strip Deep Blue | B2: 42541
B4: Beam Angle | C4: Field Angle
B5: 19 | C5: 36.6
F6: Lens Efficiency | G6: Power Consump (Watts) | H6: Efficacy (lm/W)
A7: Mode | B7: Accessory Lens | C7: Candela | D7: Field Lumens | E7: Beam Lumens
A8: RGB - full | B8: NR | C8: 18236 | D8: 2031 | E8: 966 | F8: =D8/'No Lens'!D8 -> 0.94862214 | G8: 71.8 | H8: =D8/G8 -> 28.286908
A9: Max output | B9: NR | C9: =1.13274*C8 -> 20656.647 | D9: =1.13274*D8 -> 2300.5949 | E9: =1.13274*E8 -> 1094.2268 | F9: =F8 -> 0.94862214 | G9: 101.7 | H9: =D9/G9 -> 22.621386
A10: 3200K | B10: NR | C10: =1.10642*C8 -> 20176.675 | D10: =1.10642*D8 -> 2247.139 | E10: =1.10642*E8 -> 1068.8017 | F10: =F8 -> 0.94862214 | G10: 77.5 | H10: =D10/G10 -> 28.995342
A11: 5600K | B11: NR | C11: =0.99404*C8 -> 18127.313 | D11: =0.99404*D8 -> 2018.8952 | E11: =0.99404*E8 -> 960.24264 | F11: =F8 -> 0.94862214 | G11: 71.6 | H11: =D11/G11 -> 28.196861
A12: Red | B12: NR | C12: =0.26097*C8 -> 4759.0489 | D12: =0.26097*D8 -> 530.03007 | E12: =0.26097*E8 -> 252.09702 | F12: =F8 -> 0.94862214 | G12: 27.5 | H12: =D12/G12 -> 19.273821
A13: Green | B13: NR | C13: =0.3303*C8 -> 6023.3508 | D13: =0.3303*D8 -> 670.8393 | E13: =0.3303*E8 -> 319.0698 | F13: =F8 -> 0.94862214 | G13: 30.3 | H13: =D13/G13 -> 22.139911
A14: Blue | B14: NR | C14: =0.03696*C8 -> 674.00256 | D14: =0.03696*D8 -> 75.06576 | E14: =0.03696*E8 -> 35.70336 | F14: =F8 -> 0.94862214 | G14: 31.2 | H14: =D14/G14 -> 2.4059538
B16: For Field diameter at any distance, multiply distance by | F16: =2*TAN(C5*3.1415926535/360) -> 0.66143676
B18: For Beam diameter at any distance, multiply distance by | F18: =2*TAN(B5*3.1415926535/360) -> 0.33468522
G19: Dist for 1.0 fc
B20: Throw Distance (ft) | C20: 10 | D20: 15 | E20: 20 | F20: 25 | G20: =SQRT(C8) -> 135.04073
B21: Throw Distance (m) | C21: =C20*0.3048 -> 3.048 | D21: =D20*0.3048 -> 4.572 | E21: =E20*0.3048 -> 6.096 | F21: =F20*0.3048 -> 7.62 | G21: =G20*0.3048 -> 41.160416
B22: Field Diameter (ft) | C22: =C20*F16 -> 6.6143676 | D22: =D20*F16 -> 9.9215514 | E22: =E20*F16 -> 13.228735 | F22: =F20*F16 -> 16.535919
B23: Field Diameter (m) | C23: =C21*F16 -> 2.0160592 | D23: =D21*F16 -> 3.0240889 | E23: =E21*F16 -> 4.0321185 | F23: =F21*F16 -> 5.0401481
B24: Illuminance (fc) | C24: =C8/(C20*C20) -> 182.36 | D24: =C8/(D20*D20) -> 81.048889 | E24: =C8/(E20*E20) -> 45.59 | F24: =C8/(F20*F20) -> 29.1776
B25: Illuminance (lux) | C25: =C24*10.7639 -> 1962.9048 | D25: =D24*10.7639 -> 872.40214 | E25: =E24*10.7639 -> 490.7262 | F25: =F24*10.7639 -> 314.06477
A27: Test Distance | B27: Iso-Illuminance Diagram grid lines
A28: 116.25 | B28: 12.5 | C28: 25 | D28: 37.5 | E28: 50
B29: =B28/A28 -> 0.10752688 | C29: =C28/A28 -> 0.21505376 | D29: =D28/A28 -> 0.32258065 | E29: =E28/A28 -> 0.43010753
A56: Measurement: NR Full ON RGB - Intensity
A58: Degrees | B58: (Cd)
A59: -26.83526 | B59: 0
A60: -26.78521 | B60: 0
A61: -26.73516 | B61: 0
A62: -26.68511 | B62: 0
A63: -26.63506 | B63: 0
A64: -26.585 | B64: 0
A65: -26.53495 | B65: 0
A66: -26.4849 | B66: 0
A67: -26.43485 | B67: 0
A68: -26.3848 | B68: 0
A69: -26.33475 | B69: 0
A70: -26.28469 | B70: 0
... A1131: 26.81986 | B1131: 467.2996
A1133: Degrees | B1133: (Cd)
...

Sheet NL
A2: Color Source Strip Deep Blue | B2: 42541
B4: Beam Angle | C4: Field Angle
A5: Horizontal | B5: 28 | C5: 45.1
F6: Lens Efficiency | G6: Power Consump (Watts) | H6: Efficacy (lm/W)
A7: Mode | B7: Accessory Lens | C7: Candela | D7: Field Lumens | E7: Beam Lumens
A8: RGB - full | B8: NL | C8: 17025 | D8: 2037 | E8: 1082 | F8: =D8/'No Lens'!D8 -> 0.95142457 | G8: 71.8 | H8: =D8/G8 -> 28.370474
A9: Max output | B9: NL | C9: =1.13274*C8 -> 19284.899 | D9: =1.13274*D8 -> 2307.3914 | E9: =1.13274*E8 -> 1225.6247 | F9: =F8 -> 0.95142457 | G9: 101.7 | H9: =D9/G9 -> 22.688214
A10: 3200K | B10: NL | C10: =1.10642*C8 -> 18836.8 | D10: =1.10642*D8 -> 2253.7775 | E10: =1.10642*E8 -> 1197.1464 | F10: =F8 -> 0.95142457 | G10: 77.5 | H10: =D10/G10 -> 29.081001
A11: 5600K | B11: NL | C11: =0.99404*C8 -> 16923.531 | D11: =0.99404*D8 -> 2024.8595 | E11: =0.99404*E8 -> 1075.5513 | F11: =F8 -> 0.95142457 | G11: 71.6 | H11: =D11/G11 -> 28.28016
A12: Red | B12: NL | C12: =0.26097*C8 -> 4443.0142 | D12: =0.26097*D8 -> 531.59589 | E12: =0.26097*E8 -> 282.36954 | F12: =F8 -> 0.95142457 | G12: 27.5 | H12: =D12/G12 -> 19.33076
A13: Green | B13: NL | C13: =0.3303*C8 -> 5623.3575 | D13: =0.3303*D8 -> 672.8211 | E13: =0.3303*E8 -> 357.3846 | F13: =F8 -> 0.95142457 | G13: 30.3 | H13: =D13/G13 -> 22.205317
A14: Blue | B14: NL | C14: =0.03696*C8 -> 629.244 | D14: =0.03696*D8 -> 75.28752 | E14: =0.03696*E8 -> 39.99072 | F14: =F8 -> 0.95142457 | G14: 31.2 | H14: =D14/G14 -> 2.4130615
B16: For Field diameter at any distance, multiply distance by | F16: =2*TAN(C5*3.1415926535/360) -> 0.83047265
B18: For Beam diameter at any distance, multiply distance by | F18: =2*TAN(B5*3.1415926535/360) -> 0.49865601
G19: Dist for 1.0 fc
B20: Throw Distance (ft) | C20: 10 | D20: 15 | E20: 20 | F20: 25 | G20: =SQRT(C8) -> 130.47988
B21: Throw Distance (m) | C21: =C20*0.3048 -> 3.048 | D21: =D20*0.3048 -> 4.572 | E21: =E20*0.3048 -> 6.096 | F21: =F20*0.3048 -> 7.62 | G21: =G20*0.3048 -> 39.770268
B22: Field Diameter (ft) | C22: =C20*F16 -> 8.3047265 | D22: =D20*F16 -> 12.45709 | E22: =E20*F16 -> 16.609453 | F22: =F20*F16 -> 20.761816
B23: Field Diameter (m) | C23: =C21*F16 -> 2.5312806 | D23: =D21*F16 -> 3.7969209 | E23: =E21*F16 -> 5.0625612 | F23: =F21*F16 -> 6.3282016
B24: Illuminance (fc) | C24: =C8/(C20*C20) -> 170.25 | D24: =C8/(D20*D20) -> 75.666667 | E24: =C8/(E20*E20) -> 42.5625 | F24: =C8/(F20*F20) -> 27.24
B25: Illuminance (lux) | C25: =C24*10.7639 -> 1832.554 | D25: =D24*10.7639 -> 814.46843 | E25: =E24*10.7639 -> 458.13849 | F25: =F24*10.7639 -> 293.20864
B27: Beam Angle | C27: Field Angle
A28: Vertical | B28: 14.4 | C28: 28.5
B30: For Field height at any distance, multiply distance by | F30: =2*TAN(C28*3.1415926535/360) -> 0.50793529
B32: For Beam height at any distance, multiply distance by | F32: =2*TAN(B28*3.1415926535/360) -> 0.25265876
A34: Test Distance | B34: Iso-Illuminance Diagram grid lines
A35: 95.5 | B35: 12.5 | C35: 25 | D35: 37.5 | E35: 50
B36: =B35/A35 -> 0.13089005 | C36: =C35/A35 -> 0.2617801 | D36: =D35/A35 -> 0.39267016 | E36: =E35/A35 -> 0.52356021
A42: Measurement: 30H Full ON RGB - Intensity
A44: Degrees | B44: (Cd)
A45: -31.62508 | B45: 0
A46: -31.57517 | B46: 0
A47: -31.52526 | B47: 0
A48: -31.47535 | B48: 0
A49: -31.42544 | B49: 0
A50: -31.37553 | B50: 0
A51: -31.32562 | B51: 0
A52: -31.27571 | B52: 0
A53: -31.2258 | B53: 0
A54: -31.17589 | B54: 0
...

Sheet MR
A2: Color Source Strip Deep Blue | B2: 42541
B4: Beam Angle | C4: Field Angle
B5: 29.5 | C5: 53.7
F6: Lens Efficiency | G6: Power Consump (Watts) | H6: Efficacy (lm/W)
A7: Mode | B7: Accessory Lens | C7: Candela | D7: Field Lumens | E7: Beam Lumens
A8: RGB - full | B8: MR | C8: 8562 | D8: 2135 | E8: 1075 | F8: =D8/'No Lens'!D8 -> 0.99719757 | G8: 71.8 | H8: =D8/G8 -> 29.735376
A9: Max output | B9: MR | C9: =1.13274*C8 -> 9698.5199 | D9: =1.13274*D8 -> 2418.3999 | E9: =1.13274*E8 -> 1217.6955 | F9: =F8 -> 0.99719757 | G9: 101.7 | H9: =D9/G9 -> 23.779743
A10: 3200K | B10: MR | C10: =1.10642*C8 -> 9473.168 | D10: =1.10642*D8 -> 2362.2067 | E10: =1.10642*E8 -> 1189.4015 | F10: =F8 -> 0.99719757 | G10: 77.5 | H10: =D10/G10 -> 30.480086
A11: 5600K | B11: MR | C11: =0.99404*C8 -> 8510.9705 | D11: =0.99404*D8 -> 2122.2754 | E11: =0.99404*E8 -> 1068.593 | F11: =F8 -> 0.99719757 | G11: 71.6 | H11: =D11/G11 -> 29.640718
A12: Red | B12: MR | C12: =0.26097*C8 -> 2234.4251 | D12: =0.26097*D8 -> 557.17095 | E12: =0.26097*E8 -> 280.54275 | F12: =F8 -> 0.99719757 | G12: 27.5 | H12: =D12/G12 -> 20.260762
A13: Green | B13: MR | C13: =0.3303*C8 -> 2828.0286 | D13: =0.3303*D8 -> 705.1905 | E13: =0.3303*E8 -> 355.0725 | F13: =F8 -> 0.99719757 | G13: 30.3 | H13: =D13/G13 -> 23.273614
A14: Blue | B14: MR | C14: =0.03696*C8 -> 316.45152 | D14: =0.03696*D8 -> 78.9096 | E14: =0.03696*E8 -> 39.732 | F14: =F8 -> 0.99719757 | G14: 31.2 | H14: =D14/G14 -> 2.5291538
B16: For Field diameter at any distance, multiply distance by | F16: =2*TAN(C5*3.1415926535/360) -> 1.0124643
B18: For Beam diameter at any distance, multiply distance by | F18: =2*TAN(B5*3.1415926535/360) -> 0.52655606
G19: Dist for 1.0 fc
B20: Throw Distance (ft) | C20: 10 | D20: 15 | E20: 20 | F20: 25 | G20: =SQRT(C8) -> 92.531076
B21: Throw Distance (m) | C21: =C20*0.3048 -> 3.048 | D21: =D20*0.3048 -> 4.572 | E21: =E20*0.3048 -> 6.096 | F21: =F20*0.3048 -> 7.62 | G21: =G20*0.3048 -> 28.203472
B22: Field Diameter (ft) | C22: =C20*F16 -> 10.124643 | D22: =D20*F16 -> 15.186965 | E22: =E20*F16 -> 20.249287 | F22: =F20*F16 -> 25.311608
B23: Field Diameter (m) | C23: =C21*F16 -> 3.0859913 | D23: =D21*F16 -> 4.6289869 | E23: =E21*F16 -> 6.1719826 | F23: =F21*F16 -> 7.7149782
B24: Illuminance (fc) | C24: =C8/(C20*C20) -> 85.62 | D24: =C8/(D20*D20) -> 38.053333 | E24: =C8/(E20*E20) -> 21.405 | F24: =C8/(F20*F20) -> 13.6992
B25: Illuminance (lux) | C25: =C24*10.7639 -> 921.60512 | D25: =D24*10.7639 -> 409.60227 | E25: =E24*10.7639 -> 230.40128 | F25: =F24*10.7639 -> 147.45682
A27: Test Distance | B27: Iso-Illuminance Diagram grid lines
A28: 76 | B28: 12.5 | C28: 25 | D28: 37.5 | E28: 50
B29: =B28/A28 -> 0.16447368 | C29: =C28/A28 -> 0.32894737 | D29: =D28/A28 -> 0.49342105 | E29: =E28/A28 -> 0.65789474
A56: Measurement: MR Full ON RGB - Intensity
A58: Degrees | B58: (Cd)
A59: -37.74227 | B59: 0
A60: -37.68812 | B60: 0
A61: -37.63397 | B61: 0
A62: -37.57982 | B62: 0
A63: -37.52567 | B63: 0
A64: -37.47152 | B64: 0
A65: -37.41737 | B65: 0
A66: -37.36322 | B66: 0
A67: -37.30907 | B67: 0
A68: -37.25492 | B68: 0
A69: -37.20078 | B69: 0
A70: -37.14663 | B70: 0
... A1452: 37.68812 | B1452: 209.6812
A1454: Degrees | B1454: (Cd)
...

Sheet ML
A2: Color Source Strip Deep Blue | B2: 42541
B4: Beam Angle | C4: Field Angle
A5: Horizontal | B5: 28.4 | C5: 46.1
F6: Lens Efficiency | G6: Power Consump (Watts) | H6: Efficacy (lm/W)
A7: Mode | B7: Accessory Lens | C7: Candela | D7: Field Lumens | E7: Beam Lumens
A8: RGB - full | B8: ML | C8: 16968 | D8: 2070 | E8: 1110 | F8: =D8/'No Lens'!D8 -> 0.96683793 | G8: 71.8 | H8: =D8/G8 -> 28.830084
A9: Max output | B9: ML | C9: =1.13274*C8 -> 19220.332 | D9: =1.13274*D8 -> 2344.7718 | E9: =1.13274*E8 -> 1257.3414 | F9: =F8 -> 0.96683793 | G9: 101.7 | H9: =D9/G9 -> 23.05577
A10: 3200K | B10: ML | C10: =1.10642*C8 -> 18773.735 | D10: =1.10642*D8 -> 2290.2894 | E10: =1.10642*E8 -> 1228.1262 | F10: =F8 -> 0.96683793 | G10: 77.5 | H10: =D10/G10 -> 29.552121
A11: 5600K | B11: ML | C11: =0.99404*C8 -> 16866.871 | D11: =0.99404*D8 -> 2057.6628 | E11: =0.99404*E8 -> 1103.3844 | F11: =F8 -> 0.96683793 | G11: 71.6 | H11: =D11/G11 -> 28.738307
A12: Red | B12: ML | C12: =0.26097*C8 -> 4428.139 | D12: =0.26097*D8 -> 540.2079 | E12: =0.26097*E8 -> 289.6767 | F12: =F8 -> 0.96683793 | G12: 27.5 | H12: =D12/G12 -> 19.643924
A13: Green | B13: ML | C13: =0.3303*C8 -> 5604.5304 | D13: =0.3303*D8 -> 683.721 | E13: =0.3303*E8 -> 366.633 | F13: =F8 -> 0.96683793 | G13: 30.3 | H13: =D13/G13 -> 22.56505
A14: Blue | B14: ML | C14: =0.03696*C8 -> 627.13728 | D14: =0.03696*D8 -> 76.5072 | E14: =0.03696*E8 -> 41.0256 | F14: =F8 -> 0.96683793 | G14: 31.2 | H14: =D14/G14 -> 2.4521538
B16: For Field diameter at any distance, multiply distance by | F16: =2*TAN(C5*3.1415926535/360) -> 0.8510102
B18: For Beam diameter at any distance, multiply distance by | F18: =2*TAN(B5*3.1415926535/360) -> 0.5060778
G19: Dist for 1.0 fc
B20: Throw Distance (ft) | C20: 10 | D20: 15 | E20: 20 | F20: 25 | G20: =SQRT(C8) -> 130.26128
B21: Throw Distance (m) | C21: =C20*0.3048 -> 3.048 | D21: =D20*0.3048 -> 4.572 | E21: =E20*0.3048 -> 6.096 | F21: =F20*0.3048 -> 7.62 | G21: =G20*0.3048 -> 39.703637
B22: Field Diameter (ft) | C22: =C20*F16 -> 8.510102 | D22: =D20*F16 -> 12.765153 | E22: =E20*F16 -> 17.020204 | F22: =F20*F16 -> 21.275255
B23: Field Diameter (m) | C23: =C21*F16 -> 2.5938791 | D23: =D21*F16 -> 3.8908186 | E23: =E21*F16 -> 5.1877582 | F23: =F21*F16 -> 6.4846977
B24: Illuminance (fc) | C24: =C8/(C20*C20) -> 169.68 | D24: =C8/(D20*D20) -> 75.413333 | E24: =C8/(E20*E20) -> 42.42 | F24: =C8/(F20*F20) -> 27.1488
B25: Illuminance (lux) | C25: =C24*10.7639 -> 1826.4186 | D25: =D24*10.7639 -> 811.74158 | E25: =E24*10.7639 -> 456.60464 | F25: =F24*10.7639 -> 292.22697
B27: Beam Angle | C27: Field Angle
A28: Vertical | B28: 14.5 | C28: 28.5
B30: For Field height at any distance, multiply distance by | F30: =2*TAN(C28*3.1415926535/360) -> 0.50793529
B32: For Beam height at any distance, multiply distance by | F32: =2*TAN(B28*3.1415926535/360) -> 0.25443214
A34: Test Distance | B34: Iso-Illuminance Diagram grid lines
A35: 95.5 | B35: 12.5 | C35: 25 | D35: 37.5 | E35: 50
B36: =B35/A35 -> 0.13089005 | C36: =C35/A35 -> 0.2617801 | D36: =D35/A35 -> 0.39267016 | E36: =E35/A35 -> 0.52356021
A42: Measurement: 40H Full ON RGB - Intensity
A44: Degrees | B44: (Cd)
A45: -31.62508 | B45: 0
A46: -31.57517 | B46: 0
A47: -31.52526 | B47: 0
A48: -31.47535 | B48: 0
A49: -31.42544 | B49: 0
A50: -31.37553 | B50: 0
A51: -31.32562 | B51: 0
A52: -31.27571 | B52: 0
A53: -31.2258 | B53: 0
A54: -31.17589 | B54: 0
...

Sheet WR
A2: Color Source Strip Deep Blue | B2: 42541
B4: Beam Angle | C4: Field Angle
B5: 42 | C5: 72.4
F6: Lens Efficiency | G6: Power Consump (Watts) | H6: Efficacy (lm/W)
A7: Mode | B7: Accessory Lens | C7: Candela | D7: Field Lumens | E7: Beam Lumens
A8: RGB - full | B8: WR | C8: 4778 | D8: 2168 | E8: 1084 | F8: =D8/'No Lens'!D8 -> 1.0126109 | G8: 71.8 | H8: =D8/G8 -> 30.194986
A9: Max output | B9: WR | C9: =1.13274*C8 -> 5412.2317 | D9: =1.13274*D8 -> 2455.7803 | E9: =1.13274*E8 -> 1227.8902 | F9: =F8 -> 1.0126109 | G9: 101.7 | H9: =D9/G9 -> 24.147299
A10: 3200K | B10: WR | C10: =1.10642*C8 -> 5286.4748 | D10: =1.10642*D8 -> 2398.7186 | E10: =1.10642*E8 -> 1199.3593 | F10: =F8 -> 1.0126109 | G10: 77.5 | H10: =D10/G10 -> 30.951207
A11: 5600K | B11: WR | C11: =0.99404*C8 -> 4749.5231 | D11: =0.99404*D8 -> 2155.0787 | E11: =0.99404*E8 -> 1077.5394 | F11: =F8 -> 1.0126109 | G11: 71.6 | H11: =D11/G11 -> 30.098865
A12: Red | B12: WR | C12: =0.26097*C8 -> 1246.9147 | D12: =0.26097*D8 -> 565.78296 | E12: =0.26097*E8 -> 282.89148 | F12: =F8 -> 1.0126109 | G12: 27.5 | H12: =D12/G12 -> 20.573926
A13: Green | B13: WR | C13: =0.3303*C8 -> 1578.1734 | D13: =0.3303*D8 -> 716.0904 | E13: =0.3303*E8 -> 358.0452 | F13: =F8 -> 1.0126109 | G13: 30.3 | H13: =D13/G13 -> 23.633347
A14: Blue | B14: WR | C14: =0.03696*C8 -> 176.59488 | D14: =0.03696*D8 -> 80.12928 | E14: =0.03696*E8 -> 40.06464 | F14: =F8 -> 1.0126109 | G14: 31.2 | H14: =D14/G14 -> 2.5682462
B16: For Field diameter at any distance, multiply distance by | F16: =2*TAN(C5*3.1415926535/360) -> 1.4637787
B18: For Beam diameter at any distance, multiply distance by | F18: =2*TAN(B5*3.1415926535/360) -> 0.76772807
G19: Dist for 1.0 fc
B20: Throw Distance (ft) | C20: 10 | D20: 15 | E20: 20 | F20: 25 | G20: =SQRT(C8) -> 69.123079
B21: Throw Distance (m) | C21: =C20*0.3048 -> 3.048 | D21: =D20*0.3048 -> 4.572 | E21: =E20*0.3048 -> 6.096 | F21: =F20*0.3048 -> 7.62 | G21: =G20*0.3048 -> 21.068714
B22: Field Diameter (ft) | C22: =C20*F16 -> 14.637787 | D22: =D20*F16 -> 21.956681 | E22: =E20*F16 -> 29.275574 | F22: =F20*F16 -> 36.594468
B23: Field Diameter (m) | C23: =C21*F16 -> 4.4615975 | D23: =D21*F16 -> 6.6923963 | E23: =E21*F16 -> 8.9231951 | F23: =F21*F16 -> 11.153994
B24: Illuminance (fc) | C24: =C8/(C20*C20) -> 47.78 | D24: =C8/(D20*D20) -> 21.235556 | E24: =C8/(E20*E20) -> 11.945 | F24: =C8/(F20*F20) -> 7.6448
B25: Illuminance (lux) | C25: =C24*10.7639 -> 514.29914 | D25: =D24*10.7639 -> 228.5774 | E25: =E24*10.7639 -> 128.57479 | F25: =F24*10.7639 -> 82.287863
A27: Test Distance | B27: Iso-Illuminance Diagram grid lines
A28: 56.5 | B28: 12.5 | C28: 25 | D28: 37.5 | E28: 50
B29: =B28/A28 -> 0.22123894 | C29: =C28/A28 -> 0.44247788 | D29: =D28/A28 -> 0.66371681 | E29: =E28/A28 -> 0.88495575
A56: Measurement: WR Full ON RGB - Intensity
A58: Degrees | B58: (Cd)
A59: -46.153 | B59: 0
A60: -46.08679 | B60: 0
A61: -46.02057 | B61: 0
A62: -45.95435 | B62: 0
A63: -45.88814 | B63: 0
A64: -45.82192 | B64: 0
A65: -45.7557 | B65: 0
A66: -45.68949 | B66: 0
A67: -45.62327 | B67: 0
A68: -45.55705 | B68: 0
A69: -45.49084 | B69: 0
A70: -45.42462 | B70: 0
... A1452: 46.08679 | B1452: 171.2149
A1454: Degrees | B1454: (Cd)
...

Sheet WL
A2: Color Source Strip Deep Blue | B2: 42541
B4: Beam Angle | C4: Field Angle
A5: Horizontal | B5: 66.4 | C5: 91.7
F6: Lens Efficiency | G6: Power Consump (Watts) | H6: Efficacy (lm/W)
A7: Mode | B7: Accessory Lens | C7: Candela | D7: Field Lumens | E7: Beam Lumens
A8: RGB - full | B8: WL | C8: 8016 | D8: 2141 | E8: 1030 | F8: =D8/'No Lens'!D8 -> 1 | G8: 71.8 | H8: =D8/G8 -> 29.818942
A9: Max output | B9: WL | C9: =1.1601*C8 -> 9299.3616 | D9: =1.1601*D8 -> 2483.7741 | E9: =1.1601*E8 -> 1194.903 | F9: =F8 -> 1 | G9: 101.7 | H9: =D9/G9 -> 24.422558
A10: 3200K | B10: WL | C10: =1.0656*C8 -> 8541.8496 | D10: =1.0656*D8 -> 2281.4496 | E10: =1.0656*E8 -> 1097.568 | F10: =F8 -> 1 | G10: 77.5 | H10: =D10/G10 -> 29.438059
A11: 5600K | B11: WL | C11: =1.0011*C8 -> 8024.8176 | D11: =1.0011*D8 -> 2143.3551 | E11: =1.0011*E8 -> 1031.133 | F11: =F8 -> 1 | G11: 71.6 | H11: =D11/G11 -> 29.935127
A12: Red | B12: WL | C12: =0.2917*C8 -> 2338.2672 | D12: =0.2917*D8 -> 624.5297 | E12: =0.2917*E8 -> 300.451 | F12: =F8 -> 1 | G12: 27.5 | H12: =D12/G12 -> 22.710171
A13: Green | B13: WL | C13: =0.33689*C8 -> 2700.5102 | D13: =0.33689*D8 -> 721.28149 | E13: =0.33689*E8 -> 346.9967 | F13: =F8 -> 1 | G13: 30.3 | H13: =D13/G13 -> 23.80467
A14: Blue | B14: WL | C14: =0.051948*C8 -> 416.41517 | D14: =0.051948*D8 -> 111.22067 | E14: =0.051948*E8 -> 53.50644 | F14: =F8 -> 1 | G14: 31.2 | H14: =D14/G14 -> 3.564765
B16: For Field diameter at any distance, multiply distance by | F16: =2*TAN(C5*3.1415926535/360) -> 2.0602393
B18: For Beam diameter at any distance, multiply distance by | F18: =2*TAN(B5*3.1415926535/360) -> 1.3087633
G19: Dist for 1.0 fc
B20: Throw Distance (ft) | C20: 10 | D20: 15 | E20: 20 | F20: 25 | G20: =SQRT(C8) -> 89.532117
B21: Throw Distance (m) | C21: =C20*0.3048 -> 3.048 | D21: =D20*0.3048 -> 4.572 | E21: =E20*0.3048 -> 6.096 | F21: =F20*0.3048 -> 7.62 | G21: =G20*0.3048 -> 27.289389
B22: Field Diameter (ft) | C22: =C20*F16 -> 20.602393 | D22: =D20*F16 -> 30.903589 | E22: =E20*F16 -> 41.204786 | F22: =F20*F16 -> 51.505982
B23: Field Diameter (m) | C23: =C21*F16 -> 6.2796093 | D23: =D21*F16 -> 9.419414 | E23: =E21*F16 -> 12.559219 | F23: =F21*F16 -> 15.699023
B24: Illuminance (fc) | C24: =C8/(C20*C20) -> 80.16 | D24: =C8/(D20*D20) -> 35.626667 | E24: =C8/(E20*E20) -> 20.04 | F24: =C8/(F20*F20) -> 12.8256
B25: Illuminance (lux) | C25: =C24*10.7639 -> 862.83422 | D25: =D24*10.7639 -> 383.48188 | E25: =E24*10.7639 -> 215.70856 | F25: =F24*10.7639 -> 138.05348
B27: Beam Angle | C27: Field Angle
A28: Vertical | B28: 14.8 | C28: 31
B30: For Field height at any distance, multiply distance by | F30: =2*TAN(C28*3.1415926535/360) -> 0.55464909
B32: For Beam height at any distance, multiply distance by | F32: =2*TAN(B28*3.1415926535/360) -> 0.25975465
A34: Test Distance | B34: Iso-Illuminance Diagram grid lines
A35: 45.75 | B35: 12.5 | C35: 25 | D35: 37.5 | E35: 50
B36: =B35/A35 -> 0.27322404 | C36: =C35/A35 -> 0.54644809 | D36: =D35/A35 -> 0.81967213 | E36: =E35/A35 -> 1.0928962
A42: Measurement: 50H Full ON RGB - Intensity
A44: Degrees | B44: (Cd)
A45: -52.12408 | B45: 0
A46: -52.04929 | B46: 0
A47: -51.97451 | B47: 0
A48: -51.89973 | B48: 0
A49: -51.82494 | B49: 0
A50: -51.75016 | B50: 0
A51: -51.67538 | B51: 0
A52: -51.60059 | B52: 0
A53: -51.52581 | B53: 0
A54: -51.45103 | B54: 0
...

Sheet XWR
A2: Color Source Strip Deep Blue | B2: 42541
B4: Beam Angle | C4: Field Angle
B5: 65.8 | C5: 99.6
F6: Lens Efficiency | G6: Power Consump (Watts) | H6: Efficacy (lm/W)
A7: Mode | B7: Accessory Lens | C7: Candela | D7: Field Lumens | E7: Beam Lumens
A8: RGB - full | B8: XWR | C8: 2324 | D8: 2244 | E8: 1207 | F8: =D8/'No Lens'!D8 -> 1.0481084 | G8: 71.8 | H8: =D8/G8 -> 31.253482
A9: Max output | B9: XWR | C9: =1.13274*C8 -> 2632.4878 | D9: =1.13274*D8 -> 2541.8686 | E9: =1.13274*E8 -> 1367.2172 | F9: =F8 -> 1.0481084 | G9: 101.7 | H9: =D9/G9 -> 24.993791
A10: 3200K | B10: XWR | C10: =1.10642*C8 -> 2571.3201 | D10: =1.10642*D8 -> 2482.8065 | E10: =1.10642*E8 -> 1335.4489 | F10: =F8 -> 1.0481084 | G10: 77.5 | H10: =D10/G10 -> 32.036213
A11: 5600K | B11: XWR | C11: =0.99404*C8 -> 2310.149 | D11: =0.99404*D8 -> 2230.6258 | E11: =0.99404*E8 -> 1199.8063 | F11: =F8 -> 1.0481084 | G11: 71.6 | H11: =D11/G11 -> 31.153991
A12: Red | B12: XWR | C12: =0.26097*C8 -> 606.49428 | D12: =0.26097*D8 -> 585.61668 | E12: =0.26097*E8 -> 314.99079 | F12: =F8 -> 1.0481084 | G12: 27.5 | H12: =D12/G12 -> 21.295152
A13: Green | B13: XWR | C13: =0.3303*C8 -> 767.6172 | D13: =0.3303*D8 -> 741.1932 | E13: =0.3303*E8 -> 398.6721 | F13: =F8 -> 1.0481084 | G13: 30.3 | H13: =D13/G13 -> 24.461822
A14: Blue | B14: XWR | C14: =0.03696*C8 -> 85.89504 | D14: =0.03696*D8 -> 82.93824 | E14: =0.03696*E8 -> 44.61072 | F14: =F8 -> 1.0481084 | G14: 31.2 | H14: =D14/G14 -> 2.6582769
B16: For Field diameter at any distance, multiply distance by | F16: =2*TAN(C5*3.1415926535/360) -> 2.3666804
B18: For Beam diameter at any distance, multiply distance by | F18: =2*TAN(B5*3.1415926535/360) -> 1.293858
G19: Dist for 1.0 fc
B20: Throw Distance (ft) | C20: 10 | D20: 15 | E20: 20 | F20: 25 | G20: =SQRT(C8) -> 48.207883
B21: Throw Distance (m) | C21: =C20*0.3048 -> 3.048 | D21: =D20*0.3048 -> 4.572 | E21: =E20*0.3048 -> 6.096 | F21: =F20*0.3048 -> 7.62 | G21: =G20*0.3048 -> 14.693763
B22: Field Diameter (ft) | C22: =C20*F16 -> 23.666804 | D22: =D20*F16 -> 35.500206 | E22: =E20*F16 -> 47.333608 | F22: =F20*F16 -> 59.16701
B23: Field Diameter (m) | C23: =C21*F16 -> 7.2136419 | D23: =D21*F16 -> 10.820463 | E23: =E21*F16 -> 14.427284 | F23: =F21*F16 -> 18.034105
B24: Illuminance (fc) | C24: =C8/(C20*C20) -> 23.24 | D24: =C8/(D20*D20) -> 10.328889 | E24: =C8/(E20*E20) -> 5.81 | F24: =C8/(F20*F20) -> 3.7184
B25: Illuminance (lux) | C25: =C24*10.7639 -> 250.15304 | D25: =D24*10.7639 -> 111.17913 | E25: =E24*10.7639 -> 62.538259 | F25: =F24*10.7639 -> 40.024486
A27: Test Distance | B27: Iso-Illuminance Diagram grid lines
A28: 44.5 | B28: 12.5 | C28: 25 | D28: 37.5 | E28: 50
B29: =B28/A28 -> 0.28089888 | C29: =C28/A28 -> 0.56179775 | D29: =D28/A28 -> 0.84269663 | E29: =E28/A28 -> 1.1235955
A56: Measurement: XWR Full ON RGB - Intensity
A58: Degrees | B58: (Cd)
A59: -52.89671 | B59: 0
A60: -52.82081 | B60: 0
A61: -52.74492 | B61: 0
A62: -52.66903 | B62: 0
A63: -52.59314 | B63: 0
A64: -52.51725 | B64: 0
A65: -52.44135 | B65: 0
A66: -52.36546 | B66: 0
A67: -52.28957 | B67: 0
A68: -52.21368 | B68: 0
A69: -52.13779 | B69: 0
A70: -52.06189 | B70: 0
... A1452: 52.82081 | B1452: 39.81509
A1454: Degrees | B1454: (Cd)
...

Sheet XWL
A2: Color Source Strip Deep Blue | B2: 42541
B4: Beam Angle | C4: Field Angle
A5: Horizontal | B5: 65.4 | C5: 87.6
F6: Lens Efficiency | G6: Power Consump (Watts) | H6: Efficacy (lm/W)
A7: Mode | B7: Accessory Lens | C7: Candela | D7: Field Lumens | E7: Beam Lumens
A8: RGB - full | B8: XWL | C8: 8128 | D8: 2137 | E8: 1065 | F8: =D8/'No Lens'!D8 -> 0.99813171 | G8: 71.8 | H8: =D8/G8 -> 29.763231
A9: Max output | B9: XWL | C9: =1.13274*C8 -> 9206.9107 | D9: =1.13274*D8 -> 2420.6654 | E9: =1.13274*E8 -> 1206.3681 | F9: =F8 -> 0.99813171 | G9: 101.7 | H9: =D9/G9 -> 23.802019
A10: 3200K | B10: XWL | C10: =1.10642*C8 -> 8992.9818 | D10: =1.10642*D8 -> 2364.4195 | E10: =1.10642*E8 -> 1178.3373 | F10: =F8 -> 0.99813171 | G10: 77.5 | H10: =D10/G10 -> 30.508639
A11: 5600K | B11: XWL | C11: =0.99404*C8 -> 8079.5571 | D11: =0.99404*D8 -> 2124.2635 | E11: =0.99404*E8 -> 1058.6526 | F11: =F8 -> 0.99813171 | G11: 71.6 | H11: =D11/G11 -> 29.668484
A12: Red | B12: XWL | C12: =0.26097*C8 -> 2121.1642 | D12: =0.26097*D8 -> 557.69289 | E12: =0.26097*E8 -> 277.93305 | F12: =F8 -> 0.99813171 | G12: 27.5 | H12: =D12/G12 -> 20.279741
A13: Green | B13: XWL | C13: =0.3303*C8 -> 2684.6784 | D13: =0.3303*D8 -> 705.8511 | E13: =0.3303*E8 -> 351.7695 | F13: =F8 -> 0.99813171 | G13: 30.3 | H13: =D13/G13 -> 23.295416
A14: Blue | B14: XWL | C14: =0.03696*C8 -> 300.41088 | D14: =0.03696*D8 -> 78.98352 | E14: =0.03696*E8 -> 39.3624 | F14: =F8 -> 0.99813171 | G14: 31.2 | H14: =D14/G14 -> 2.5315231
B16: For Field diameter at any distance, multiply distance by | F16: =2*TAN(C5*3.1415926535/360) -> 1.917931
B18: For Beam diameter at any distance, multiply distance by | F18: =2*TAN(B5*3.1415926535/360) -> 1.2839772
G19: Dist for 1.0 fc
B20: Throw Distance (ft) | C20: 10 | D20: 15 | E20: 20 | F20: 25 | G20: =SQRT(C8) -> 90.155421
B21: Throw Distance (m) | C21: =C20*0.3048 -> 3.048 | D21: =D20*0.3048 -> 4.572 | E21: =E20*0.3048 -> 6.096 | F21: =F20*0.3048 -> 7.62 | G21: =G20*0.3048 -> 27.479372
B22: Field Diameter (ft) | C22: =C20*F16 -> 19.17931 | D22: =D20*F16 -> 28.768966 | E22: =E20*F16 -> 38.358621 | F22: =F20*F16 -> 47.948276
B23: Field Diameter (m) | C23: =C21*F16 -> 5.8458538 | D23: =D21*F16 -> 8.7687807 | E23: =E21*F16 -> 11.691708 | F23: =F21*F16 -> 14.614635
B24: Illuminance (fc) | C24: =C8/(C20*C20) -> 81.28 | D24: =C8/(D20*D20) -> 36.124444 | E24: =C8/(E20*E20) -> 20.32 | F24: =C8/(F20*F20) -> 13.0048
B25: Illuminance (lux) | C25: =C24*10.7639 -> 874.88979 | D25: =D24*10.7639 -> 388.83991 | E25: =E24*10.7639 -> 218.72245 | F25: =F24*10.7639 -> 139.98237
B27: Beam Angle | C27: Field Angle
A28: Vertical | B28: 15 | C28: 31.3
B30: For Field height at any distance, multiply distance by | F30: =2*TAN(C28*3.1415926535/360) -> 0.56029188
B32: For Beam height at any distance, multiply distance by | F32: =2*TAN(B28*3.1415926535/360) -> 0.263305
A34: Test Distance | B34: Iso-Illuminance Diagram grid lines
A35: 44.5 | B35: 12.5 | C35: 25 | D35: 37.5 | E35: 50
B36: =B35/A35 -> 0.28089888 | C36: =C35/A35 -> 0.56179775 | D36: =D35/A35 -> 0.84269663 | E36: =E35/A35 -> 1.1235955
A42: Measurement: 80H Full ON RGB - Intensity
A44: Degrees | B44: (Cd)
A45: -52.89671 | B45: 0
A46: -52.82081 | B46: 0
A47: -52.74492 | B47: 0
A48: -52.66903 | B48: 0
A49: -52.59314 | B49: 0
A50: -52.51725 | B50: 0
A51: -52.44135 | B51: 0
A52: -52.36546 | B52: 0
A53: -52.28957 | B53: 0
A54: -52.21368 | B54: 0
...

Sheet Multipliers
A1: Mode | B1: Setting | C1: Field Lumens | D1: Candela | E1: lumen m.f. | F1: candela m.f. | G1: average
A2: RGB | B2: full | C2: 2141 | D2: 31917 | E2: 1 | F2: 1 | G2: 1
A3: RGB | B3: 3200K | C3: 2366 | D3: 35356 | E3: =C3/C$2 -> 1.1050911 | F3: =D3/D$2 -> 1.1077482 | G3: =AVERAGE(E3:F3) -> 1.1064197
A4: RGB | B4: 5600K | C4: 2126 | D4: 31760 | E4: =C4/C$2 -> 0.99299393 | F4: =D4/D$2 -> 0.99508099 | G4: =AVERAGE(E4:F4) -> 0.99403746
A5: RGB | B5: red | C5: 566 | D5: 8221 | E5: =C5/C$2 -> 0.26436245 | F5: =D5/D$2 -> 0.25757433 | G5: =AVERAGE(E5:F5) -> 0.26096839
A6: RGB | B6: green | C6: 675 | D6: 11022 | E6: =C6/C$2 -> 0.31527324 | F6: =D6/D$2 -> 0.34533321 | G6: =AVERAGE(E6:F6) -> 0.33030322
A7: RGB | B7: blue | C7: 81 | D7: 1152 | E7: =C7/C$2 -> 0.037832788 | F7: =D7/D$2 -> 0.036093618 | G7: =AVERAGE(E7:F7) -> 0.036963203
A8: Direct | B8: full | C8: 2429 | D8: 36097 | E8: =C8/C$2 -> 1.1345166 | F8: =D8/D$2 -> 1.1309647 | G8: =AVERAGE(E8:F8) -> 1.1327406
A9: Direct | B9: lime | C9: 1148 | D9: 16180 | E9: =C9/C$2 -> 0.53619804 | F9: =D9/D$2 -> 0.50693988 | G9: =AVERAGE(E9:F9) -> 0.52156896
A10: Direct | B10: red | C10: 562 | D10: 8144 | E10: =C10/C$2 -> 0.26249416 | F10: =D10/D$2 -> 0.25516183 | G10: =AVERAGE(E10:F10) -> 0.25882799
A11: Direct | B11: green | C11: 673 | D11: 10989 | E11: =C11/C$2 -> 0.31433909 | F11: =D11/D$2 -> 0.34429928 | G11: =AVERAGE(E11:F11) -> 0.32931919
A12: Direct | B12: blue | C12: 75 | D12: 1042 | E12: =C12/C$2 -> 0.03503036 | F12: =D12/D$2 -> 0.032647179 | G12: =AVERAGE(E12:F12) -> 0.033838769

Sheet Vivid Plots
B1: X | D1: Y | G1: factor
A2: -11.873 | B2: 0 | C2: -11.918 | D2: 1800.117 | E2: =B2*$G$2 -> 0 | F2: =D2*$G$2 -> 1800.117 | G2: 1
A3: -11.827 | B3: 0 | C3: -11.873 | D3: 1797.319 | E3: =B3*$G$2 -> 0 | F3: =D3*$G$2 -> 1797.319
A4: -11.782 | B4: 0 | C4: -11.827 | D4: 1791.486 | E4: =B4*$G$2 -> 0 | F4: =D4*$G$2 -> 1791.486
A5: -11.737 | B5: 196.884 | C5: -11.782 | D5: 1798.428 | E5: =B5*$G$2 -> 196.884 | F5: =D5*$G$2 -> 1798.428
A6: -11.692 | B6: 525.047 | C6: -11.737 | D6: 1812.132 | E6: =B6*$G$2 -> 525.047 | F6: =D6*$G$2 -> 1812.132
A7: -11.646 | B7: 848.874 | C7: -11.692 | D7: 1832.167 | E7: =B7*$G$2 -> 848.874 | F7: =D7*$G$2 -> 1832.167
A8: -11.601 | B8: 1176.61 | C8: -11.646 | D8: 1856.622 | E8: =B8*$G$2 -> 1176.61 | F8: =D8*$G$2 -> 1856.622
A9: -11.556 | B9: 1377.602 | C9: -11.601 | D9: 1884.857 | E9: =B9*$G$2 -> 1377.602 | F9: =D9*$G$2 -> 1884.857
A10: -11.51 | B10: 1389.593 | C10: -11.556 | D10: 1904.413 | E10: =B10*$G$2 -> 1389.593 | F10: =D10*$G$2 -> 1904.413
A11: -11.465 | B11: 1408.743 | C11: -11.51 | D11: 1922.055 | E11: =B11*$G$2 -> 1408.743 | F11: =D11*$G$2 -> 1922.055
A12: -11.42 | B12: 1428.719 | C12: -11.465 | D12: 1946.009 | E12: =B12*$G$2 -> 1428.719 | F12: =D12*$G$2 -> 1946.009
A13: -11.374 | B13: 1456.895 | C13: -11.42 | D13: 1969.521 | E13: =B13*$G$2 -> 1456.895 | F13: =D13*$G$2 -> 1969.521
A14: -11.329 | B14: 1474.518 | C14: -11.374 | D14: 1991.329 | E14: =B14*$G$2 -> 1474.518 | F14: =D14*$G$2 -> 1991.329
... A513: 11.873 | B513: 2026.37 | C513: 11.827 | D513: 691.503 | E513: =B513*$G$2 -> 2026.37 | F513: =D513*$G$2 -> 691.503

Sheet Paletta Plots
B1: X | D1: Y | G1: factor
A2: -29.091 | B2: 89.428 | C2: -28.113 | D2: 99.075 | E2: =B2*$G$2 -> 89.428 | F2: =D2*$G$2 -> 99.075 | G2: 1
A3: -28.983 | B3: 89.024 | C3: -28.003 | D3: 98.523 | E3: =B3*$G$2 -> 89.024 | F3: =D3*$G$2 -> 98.523
A4: -28.875 | B4: 89.641 | C4: -27.893 | D4: 98.565 | E4: =B4*$G$2 -> 89.641 | F4: =D4*$G$2 -> 98.565
A5: -28.767 | B5: 91.827 | C5: -27.782 | D5: 100.487 | E5: =B5*$G$2 -> 91.827 | F5: =D5*$G$2 -> 100.487
A6: -28.658 | B6: 91.002 | C6: -27.672 | D6: 103.273 | E6: =B6*$G$2 -> 91.002 | F6: =D6*$G$2 -> 103.273
A7: -28.55 | B7: 90.66 | C7: -27.561 | D7: 104.646 | E7: =B7*$G$2 -> 90.66 | F7: =D7*$G$2 -> 104.646
A8: -28.441 | B8: 94.133 | C8: -27.45 | D8: 106.474 | E8: =B8*$G$2 -> 94.133 | F8: =D8*$G$2 -> 106.474
A9: -28.332 | B9: 96.516 | C9: -27.339 | D9: 108.869 | E9: =B9*$G$2 -> 96.516 | F9: =D9*$G$2 -> 108.869
A10: -28.222 | B10: 98.469 | C10: -27.228 | D10: 110.904 | E10: =B10*$G$2 -> 98.469 | F10: =D10*$G$2 -> 110.904
A11: -28.113 | B11: 99.76 | C11: -27.116 | D11: 108.849 | E11: =B11*$G$2 -> 99.76 | F11: =D11*$G$2 -> 108.849
A12: -28.003 | B12: 101.809 | C12: -27.004 | D12: 109.096 | E12: =B12*$G$2 -> 101.809 | F12: =D12*$G$2 -> 109.096
A13: -27.893 | B13: 100.501 | C13: -26.892 | D13: 109.913 | E13: =B13*$G$2 -> 100.501 | F13: =D13*$G$2 -> 109.913
A14: -27.782 | B14: 100.136 | C14: -26.78 | D14: 111.807 | E14: =B14*$G$2 -> 100.136 | F14: =D14*$G$2 -> 111.807
... A447: 28.332 | B447: 106.642 | C447: 27.893 | D447: 84.191 | E447: =B447*$G$2 -> 106.642 | F447: =D447*$G$2 -> 84.191
A448: 28.441 | B448: 105.866

Sheet Lustr Plots
B1: X | D1: Y | G1: factor
A2: -32.12 | B2: 0 | C2: -32.221 | D2: 122.869 | E2: =B2*$G$2 -> 0 | F2: =D2*$G$2 -> 122.869 | G2: 1
A3: -32.019 | B3: 0 | C3: -32.12 | D3: 120.57 | E3: =B3*$G$2 -> 0 | F3: =D3*$G$2 -> 120.57
A4: -31.917 | B4: 0 | C4: -32.019 | D4: 118.22 | E4: =B4*$G$2 -> 0 | F4: =D4*$G$2 -> 118.22
A5: -31.815 | B5: 17.56 | C5: -31.917 | D5: 115.113 | E5: =B5*$G$2 -> 17.56 | F5: =D5*$G$2 -> 115.113
A6: -31.714 | B6: 47.637 | C6: -31.815 | D6: 113.676 | E6: =B6*$G$2 -> 47.637 | F6: =D6*$G$2 -> 113.676
A7: -31.611 | B7: 78.368 | C7: -31.714 | D7: 114.551 | E7: =B7*$G$2 -> 78.368 | F7: =D7*$G$2 -> 114.551
A8: -31.509 | B8: 106.086 | C8: -31.611 | D8: 117.715 | E8: =B8*$G$2 -> 106.086 | F8: =D8*$G$2 -> 117.715
A9: -31.406 | B9: 125.282 | C9: -31.509 | D9: 118.505 | E9: =B9*$G$2 -> 125.282 | F9: =D9*$G$2 -> 118.505
A10: -31.303 | B10: 125.846 | C10: -31.406 | D10: 120.722 | E10: =B10*$G$2 -> 125.846 | F10: =D10*$G$2 -> 120.722
A11: -31.2 | B11: 127.635 | C11: -31.303 | D11: 122.859 | E11: =B11*$G$2 -> 127.635 | F11: =D11*$G$2 -> 122.859
A12: -31.097 | B12: 131.411 | C12: -31.2 | D12: 126.664 | E12: =B12*$G$2 -> 131.411 | F12: =D12*$G$2 -> 126.664
A13: -30.993 | B13: 133.684 | C13: -31.097 | D13: 128.831 | E13: =B13*$G$2 -> 133.684 | F13: =D13*$G$2 -> 128.831
A14: -30.89 | B14: 131.07 | C14: -30.993 | D14: 131.048 | E14: =B14*$G$2 -> 131.07 | F14: =D14*$G$2 -> 131.048
... A513: 32.12 | B513: 120.57 | C513: 32.019 | D513: 45.122 | E513: =B513*$G$2 -> 120.57 | F513: =D513*$G$2 -> 45.122

Sheet Lenses & Diffusers
A1: Note : All measurments are with a Vivid
A2: Luminit Diffuser | B2: Side Facing LEDs | C2: Field Lumens | D2: Field Angle Horiz | E2: Field Angle Vert | F2: Lens Efficiency
A3: none | C3: 1127 | D3: 21.09 | E3: 19.14 | F3: 1
A4: 20 | B4: smooth | C4: 1034 | D4: 46.4 | E4: 44.9 | F4: 0.91748004
A5: 20 | B5: rough | C5: 1112 | D5: 47.29 | E5: 45.71 | F5: 0.98669033
A6: 30x5 | B6: rough | C6: 1078 | D6: 64.74 | E6: 25.45 | F6: 0.95652174
A7: 40 | B7: rough | C7: 1114 | D7: 74.31 | E7: 76.21 | F7: 0.98846495
A8: 60x10 | B8: rough | C8: 1062 | D8: 74.87 | E8: 30.62 | F8: 0.94232476
A9: 60 | B9: rough | C9: 1003 | D9: 74.87 | E9: 76.64 | F9: 0.88997338
A10: 75x35 | B10: rough | C10: 1031 | D10: 75* | E10: 61.68 | F10: 0.9148181 | G10: *note - we could not capture the full field width
A13: MicrolensLens | B13: Lens Efficiency | E13: Vivid Field Angle Horiz | F13: Vivid Field Angle Vert | G13: Paletta Field Angle Horiz | H13: Paletta Field Angle Vert | I13: Lustr Field Angle Horiz | J13: Lustr Field Angle Vert
B14: Vivid | C14: Paletta | D14: Lustr
A15: none | B15: na | C15: na | D15: na | E15: 18.6 | F15: 18.6 | G15: 25.7 | H15: 25.7 | I15: 26.4 | J15: 26.4 | K15: =I15-G15 -> 0.7 | L15: =J15-H15 -> 0.7
A16: H40 | B16: 0.978 | C16: 0.936 | D16: 0.935 | E16: 41.3 | F16: 21.3 | G16: 44.6 | H16: 26.8 | I16: 45.2 | J16: 27.1 | K16: =I16-G16 -> 0.6 | L16: =J16-H16 -> 0.3
A17: V40 | B17: 1.004 | C17: 0.945 | D17: 0.946 | E17: 23.5 | F17: 40.7 | G17: 28.8 | H17: 44 | I17: 28.9 | J17: 44.7 | K17: =I17-G17 -> 0.1 | L17: =J17-H17 -> 0.7
A18: H50 | B18: 0.96 | C18: 0.936 | D18: 0.951 | E18: 72.3 | F18: 21.9 | G18: 74.4 | H18: 27.1 | I18: 75 | J18: 28 | K18: =I18-G18 -> 0.6 | L18: =J18-H18 -> 0.9
A19: V50 | B19: 0.978 | C19: 0.945 | D19: 0.946 | E19: 24.8 | F19: 72.3 | G19: 29.5 | H19: 76 | I19: 31.3 | J19: 76.6 | K19: =I19-G19 -> 1.8 | L19: =J19-H19 -> 0.6
A20: H60 | B20: 0.978 | C20: 0.945 | D20: 0.957 | E20: 68.2 | F20: 21.6 | G20: 71.3 | H20: 27.3 | I20: 71.4 | J20: 27.8 | K20: =I20-G20 -> 0.1 | L20: =J20-H20 -> 0.5
A21: V60 | B21: 0.996 | C21: 0.954 | D21: 0.968 | E21: 24.9 | F21: 67.6 | G21: 30.6 | H21: 70.8 | I21: 31.3 | J21: 71.2 | K21: =I21-G21 -> 0.7 | L21: =J21-H21 -> 0.4
A22: H70 | B22: 0.96 | C22: 0.918 | D22: 0.935 | E22: 72.8 | F22: 21.7 | G22: 78 | H22: 28 | I22: 79.2 | J22: 28 | K22: =I22-G22 -> 1.2 | L22: =J22-H22 -> 0
A23: V70 | B23: 0.978 | C23: 0.918 | D23: 0.946 | E23: 25.1 | F23: 72.9 | G23: 31.3 | H23: 78.5 | I23: 31 | J23: 79.4 | K23: =I23-G23 -> -0.3 | L23: =J23-H23 -> 0.9
A24: H80 | B24: 0.924 | C24: 0.9 | D24: 0.908 | E24: ~78 | F24: 22.2 | G24: 80 | H24: 27.5 | I24: 82.5 | J24: 28.2 | K24: =I24-G24 -> 2.5 | L24: =J24-H24 -> 0.7
A25: V80 | B25: 0.951 | C25: 0.909 | D25: 0.924 | E25: 26.5 | F25: 80.3 | G25: 31 | H25: 82 | I25: 31.3 | J25: 82.5 | K25: =I25-G25 -> 0.3 | L25: =J25-H25 -> 0.5
A26: H40 + V40 | B26: 0.907 | C26: 0.864 | D26: 0.869 | E26: 44.7 | F26: 42.6 | G26: 47.6 | H26: 45.7 | I26: 48.1 | J26: 46.6 | K26: =I26-G26 -> 0.5 | L26: =J26-H26 -> 0.9
A27: H60 + V60 | B27: 0.951 | C27: 0.918 | D27: 0.924 | E27: 70.4 | F27: 70.2 | G27: 73.8 | H27: 72.3 | I27: 73.6 | J27: 72.4 | K27: =I27-G27 -> -0.2 | L27: =J27-H27 -> 0.1
A28: H40 + V60 | B28: 0.924 | C28: 0.891 | D28: 0.897 | E28: 45.3 | F28: 69.8 | G28: 48.5 | H28: 72.1 | I28: 48.8 | J28: 72.4 | K28: =I28-G28 -> 0.3 | L28: =J28-H28 -> 0.3
A29: H40 + V80 | B29: 0.889 | C29: 0.855 | D29: 0.858 | E29: 45.8 | F29: 81.4 | G29: 48.6 | H29: 82 | I29: 49.1 | J29: 82.6 | K29: =I29-G29 -> 0.5 | L29: =J29-H29 -> 0.6
K30: =AVERAGE(K16:K29) -> 0.62142857 | L30: =AVERAGE(L16:L29) -> 0.52857143

Sheet Vivid H40
A1: Selador | B1: Lamp | D1: Wattage
A2: Vivid | B2: Lumileds K2 | D2: 122 | F2: Note: Owing to the variability of LEDs, output data and color matches should be viewed as approximate
F4: Note: All data taken with room temperature fixture
B5: Beam Angle | C5: Field Angle
A6: Horizontal | B6: 28.9 | C6: 41.3
B8: Accessory Lens | C8: Candela | D8: Field Lumens | E8: Beam Lumens | F8: Lens Efficiency | G8: Efficacy
B9: H40 | C9: 12130 | D9: 1100 | E9: 650 | F9: =D9/1125 -> 0.97777778 | G9: =D9/D2 -> 9.0163934
B12: For Field diameter at any distance, multiply distance by | F12: =2*TAN(C6*3.1415926535/360) -> 0.75374315
B14: For Beam diameter at any distance, multiply distance by | F14: =2*TAN(B6*3.1415926535/360) -> 0.51537353
B16: Throw Distance (ft) | C16: 10 | D16: 15 | E16: 20 | F16: 25
B17: Throw Distance (m) | C17: =C16*0.3048 -> 3.048 | D17: =D16*0.3048 -> 4.572 | E17: =E16*0.3048 -> 6.096 | F17: =F16*0.3048 -> 7.62
B18: Field Diameter (ft) | C18: =C16*F12 -> 7.5374315 | D18: =D16*F12 -> 11.306147 | E18: =E16*F12 -> 15.074863 | F18: =F16*F12 -> 18.843579
B19: Field Diameter (m) | C19: =C17*F12 -> 2.2974091 | D19: =D17*F12 -> 3.4461137 | E19: =E17*F12 -> 4.5948182 | F19: =F17*F12 -> 5.7435228
B20: Illuminance (fc) | C20: =C9/(C16*C16) -> 121.3 | D20: =C9/(D16*D16) -> 53.911111 | E20: =C9/(E16*E16) -> 30.325 | F20: =C9/(F16*F16) -> 19.408
B21: Illuminance (lux) | C21: =C20*10.7639 -> 1305.6611 | D21: =D20*10.7639 -> 580.29381 | E21: =E20*10.7639 -> 326.41527 | F21: =F20*10.7639 -> 208.90577
A24: Test Distance | B24: Iso-Illuminance Diagram grid lines
A25: 72 | B25: 10 | C25: 20 | D25: 30 | E25: 40
B26: =B25/A25 -> 0.13888889 | C26: =C25/A25 -> 0.27777778 | D26: =D25/A25 -> 0.41666667 | E26: =E25/A25 -> 0.55555556
B28: Beam Angle | C28: Field Angle
A29: Vertical | B29: 10 | C29: 21.3
B32: For Field diameter at any distance, multiply distance by | F32: =2*TAN(C29*3.1415926535/360) -> 0.37609658
B34: For Beam diameter at any distance, multiply distance by | F34: =2*TAN(B29*3.1415926535/360) -> 0.17497733
B36: Throw Distance (ft) | C36: 10 | D36: 15 | E36: 20 | F36: 25
B37: Throw Distance (m) | C37: =C36*0.3048 -> 3.048 | D37: =D36*0.3048 -> 4.572 | E37: =E36*0.3048 -> 6.096 | F37: =F36*0.3048 -> 7.62
B38: Field Diameter (ft) | C38: =C36*F32 -> 3.7609658 | D38: =D36*F32 -> 5.6414487 | E38: =E36*F32 -> 7.5219316 | F38: =F36*F32 -> 9.4024145
B39: Field Diameter (m) | C39: =C37*F32 -> 1.1463424 | D39: =D37*F32 -> 1.7195136 | E39: =E37*F32 -> 2.2926847 | F39: =F37*F32 -> 2.8658559
B40: Illuminance (fc) | C40: =C9/(C36*C36) -> 121.3 | D40: =C9/(D36*D36) -> 53.911111 | E40: =C9/(E36*E36) -> 30.325 | F40: =C9/(F36*F36) -> 19.408
B41: Illuminance (lux) | C41: =C40*10.7639 -> 1305.6611 | D41: =D40*10.7639 -> 580.29381 | E41: =E40*10.7639 -> 326.41527 | F41: =F40*10.7639 -> 208.90577
B43: X | D43: Y
A44: -17.18 | B44: 0 | C44: -17.243 | D44: 893.935
A45: -17.117 | B45: 0 | C45: -17.18 | D45: 903.395
A46: -17.053 | B46: 0 | C46: -17.117 | D46: 909.77
A47: -16.99 | B47: 128.031 | C47: -17.053 | D47: 920.21
A48: -16.926 | B48: 344.851 | C48: -16.99 | D48: 930.746
A49: -16.862 | B49: 562.378 | C49: -16.926 | D49: 941.893
A50: -16.799 | B50: 780.611 | C50: -16.862 | D50: 953.134
A51: -16.735 | B51: 914.197 | C51: -16.799 | D51: 968.358
A52: -16.671 | B52: 926.352 | C52: -16.735 | D52: 984.753
A53: -16.608 | B53: 939.397 | C53: -16.671 | D53: 1004.599
A54: -16.544 | B54: 950.026 | C54: -16.608 | D54: 1020.816
...

Sheet Vivid V40 
A1: Selador | B1: Lamp | D1: Wattage
A2: Vivid | B2: Lumileds K2 | D2: 122 | F2: Note: Owing to the variability of LEDs, output data and color matches should be viewed as approximate
F4: Note: All data taken with room temperature fixture
B5: Beam Angle | C5: Field Angle
A6: Horizontal | B6: 11.8 | C6: 23.5
B8: Accessory Lens | C8: Candela | D8: Field Lumens | E8: Beam Lumens | F8: Lens Efficiency | G8: Efficacy
B9: V40 | C9: 10660 | D9: 1130 | E9: 710 | F9: =D9/1125 -> 1.0044444 | G9: =D9/D2 -> 9.2622951
B12: For Field diameter at any distance, multiply distance by | F12: =2*TAN(C6*3.1415926535/360) -> 0.4160006
B14: For Beam diameter at any distance, multiply distance by | F14: =2*TAN(B6*3.1415926535/360) -> 0.20667989
B16: Throw Distance (ft) | C16: 10 | D16: 15 | E16: 20 | F16: 25
B17: Throw Distance (m) | C17: =C16*0.3048 -> 3.048 | D17: =D16*0.3048 -> 4.572 | E17: =E16*0.3048 -> 6.096 | F17: =F16*0.3048 -> 7.62
B18: Field Diameter (ft) | C18: =C16*F12 -> 4.160006 | D18: =D16*F12 -> 6.240009 | E18: =E16*F12 -> 8.320012 | F18: =F16*F12 -> 10.400015
B19: Field Diameter (m) | C19: =C17*F12 -> 1.2679698 | D19: =D17*F12 -> 1.9019547 | E19: =E17*F12 -> 2.5359396 | F19: =F17*F12 -> 3.1699246
B20: Illuminance (fc) | C20: =C9/(C16*C16) -> 106.6 | D20: =C9/(D16*D16) -> 47.377778 | E20: =C9/(E16*E16) -> 26.65 | F20: =C9/(F16*F16) -> 17.056
B21: Illuminance (lux) | C21: =C20*10.7639 -> 1147.4317 | D21: =D20*10.7639 -> 509.96966 | E21: =E20*10.7639 -> 286.85793 | F21: =F20*10.7639 -> 183.58908
A24: Test Distance | B24: Iso-Illuminance Diagram grid lines
A25: 72 | B25: 10 | C25: 20 | D25: 30 | E25: 40
B26: =B25/A25 -> 0.13888889 | C26: =C25/A25 -> 0.27777778 | D26: =D25/A25 -> 0.41666667 | E26: =E25/A25 -> 0.55555556
B28: Beam Angle | C28: Field Angle
A29: Vertical | B29: 28.9 | C29: 40.7
B32: For Field diameter at any distance, multiply distance by | F32: =2*TAN(C29*3.1415926535/360) -> 0.74180726
B34: For Beam diameter at any distance, multiply distance by | F34: =2*TAN(B29*3.1415926535/360) -> 0.51537353
B36: Throw Distance (ft) | C36: =C16 -> 10 | D36: =D16 -> 15 | E36: =E16 -> 20 | F36: =F16 -> 25
B37: Throw Distance (m) | C37: =C36*0.3048 -> 3.048 | D37: =D36*0.3048 -> 4.572 | E37: =E36*0.3048 -> 6.096 | F37: =F36*0.3048 -> 7.62
B38: Field Diameter (ft) | C38: =C36*F32 -> 7.4180726 | D38: =D36*F32 -> 11.127109 | E38: =E36*F32 -> 14.836145 | F38: =F36*F32 -> 18.545181
B39: Field Diameter (m) | C39: =C37*F32 -> 2.2610285 | D39: =D37*F32 -> 3.3915428 | E39: =E37*F32 -> 4.522057 | F39: =F37*F32 -> 5.6525713
B40: Illuminance (fc) | C40: =C9/(C36*C36) -> 106.6 | D40: =C9/(D36*D36) -> 47.377778 | E40: =C9/(E36*E36) -> 26.65 | F40: =C9/(F36*F36) -> 17.056
B41: Illuminance (lux) | C41: =C40*10.7639 -> 1147.4317 | D41: =D40*10.7639 -> 509.96966 | E41: =E40*10.7639 -> 286.85793 | F41: =F40*10.7639 -> 183.58908
B43: X | D43: Y
A44: -32.12 | B44: 0 | C44: -32.221 | D44: 137.863
A45: -32.019 | B45: 0 | C45: -32.12 | D45: 137.401
A46: -31.917 | B46: 0 | C46: -32.019 | D46: 136.734
A47: -31.815 | B47: 8.4 | C47: -31.917 | D47: 136.325
A48: -31.714 | B48: 22.096 | C48: -31.815 | D48: 137.52
A49: -31.611 | B49: 36.648 | C49: -31.714 | D49: 140
A50: -31.509 | B50: 51.834 | C50: -31.611 | D50: 141.561
A51: -31.406 | B51: 60.637 | C51: -31.509 | D51: 142.467
A52: -31.303 | B52: 60.779 | C52: -31.406 | D52: 141.743
A53: -31.2 | B53: 61.005 | C53: -31.303 | D53: 141.705
A54: -31.097 | B54: 60.806 | C54: -31.2 | D54: 145.02
...

Sheet Vivid H50
A1: Selador | B1: Lamp | D1: Wattage
A2: Vivid | B2: Lumileds K2 | D2: 122 | F2: Note: Owing to the variability of LEDs, output data and color matches should be viewed as approximate
F4: Note: All data taken with room temperature fixture
B5: Beam Angle | C5: Field Angle
A6: Horizontal | B6: 58.7 | C6: 72.3
B8: Accessory Lens | C8: Candela | D8: Field Lumens | E8: Beam Lumens | F8: Lens Efficiency | G8: Efficacy
B9: H50 | C9: 6450 | D9: 1080 | E9: 570 | F9: =D9/1125 -> 0.96 | G9: =D9/D2 -> 8.852459
B12: For Field diameter at any distance, multiply distance by | F12: =2*TAN(C6*3.1415926535/360) -> 1.4611002
B14: For Beam diameter at any distance, multiply distance by | F14: =2*TAN(B6*3.1415926535/360) -> 1.1246437
B16: Throw Distance (ft) | C16: 10 | D16: 15 | E16: 20 | F16: 25
B17: Throw Distance (m) | C17: =C16*0.3048 -> 3.048 | D17: =D16*0.3048 -> 4.572 | E17: =E16*0.3048 -> 6.096 | F17: =F16*0.3048 -> 7.62
B18: Field Diameter (ft) | C18: =C16*F12 -> 14.611002 | D18: =D16*F12 -> 21.916503 | E18: =E16*F12 -> 29.222004 | F18: =F16*F12 -> 36.527505
B19: Field Diameter (m) | C19: =C17*F12 -> 4.4534334 | D19: =D17*F12 -> 6.6801501 | E19: =E17*F12 -> 8.9068668 | F19: =F17*F12 -> 11.133584
B20: Illuminance (fc) | C20: =C9/(C16*C16) -> 64.5 | D20: =C9/(D16*D16) -> 28.666667 | E20: =C9/(E16*E16) -> 16.125 | F20: =C9/(F16*F16) -> 10.32
B21: Illuminance (lux) | C21: =C20*10.7639 -> 694.27155 | D21: =D20*10.7639 -> 308.56513 | E21: =E20*10.7639 -> 173.56789 | F21: =F20*10.7639 -> 111.08345
A24: Test Distance | B24: Iso-Illuminance Diagram grid lines
A25: 61 | B25: 10 | C25: 20 | D25: 30 | E25: 40
B26: =B25/A25 -> 0.16393443 | C26: =C25/A25 -> 0.32786885 | D26: =D25/A25 -> 0.49180328 | E26: =E25/A25 -> 0.6557377
B28: Beam Angle | C28: Field Angle
A29: Vertical | B29: 10 | C29: 21.9
B32: For Field diameter at any distance, multiply distance by | F32: =2*TAN(C29*3.1415926535/360) -> 0.38694965
B34: For Beam diameter at any distance, multiply distance by | F34: =2*TAN(B29*3.1415926535/360) -> 0.17497733
B36: Throw Distance (ft) | C36: =C16 -> 10 | D36: =D16 -> 15 | E36: =E16 -> 20 | F36: =F16 -> 25
B37: Throw Distance (m) | C37: =C36*0.3048 -> 3.048 | D37: =D36*0.3048 -> 4.572 | E37: =E36*0.3048 -> 6.096 | F37: =F36*0.3048 -> 7.62
B38: Field Diameter (ft) | C38: =C36*F32 -> 3.8694965 | D38: =D36*F32 -> 5.8042448 | E38: =E36*F32 -> 7.738993 | F38: =F36*F32 -> 9.6737413
B39: Field Diameter (m) | C39: =C37*F32 -> 1.1794225 | D39: =D37*F32 -> 1.7691338 | E39: =E37*F32 -> 2.3588451 | F39: =F37*F32 -> 2.9485563
B40: Illuminance (fc) | C40: =C9/(C36*C36) -> 64.5 | D40: =C9/(D36*D36) -> 28.666667 | E40: =C9/(E36*E36) -> 16.125 | F40: =C9/(F36*F36) -> 10.32
B41: Illuminance (lux) | C41: =C40*10.7639 -> 694.27155 | D41: =D40*10.7639 -> 308.56513 | E41: =E40*10.7639 -> 173.56789 | F41: =F40*10.7639 -> 111.08345
B43: X | D43: Y
A44: -36.538 | B44: 0 | C44: -36.646 | D44: 38.886
A45: -36.431 | B45: 0 | C45: -36.538 | D45: 39.463
A46: -36.323 | B46: 0 | C46: -36.431 | D46: 39.47
A47: -36.214 | B47: 109.477 | C47: -36.323 | D47: 38.322
A48: -36.106 | B48: 299.625 | C48: -36.214 | D48: 37.981
A49: -35.997 | B49: 494.895 | C49: -36.106 | D49: 39.053
A50: -35.888 | B50: 697.62 | C50: -35.997 | D50: 38.639
A51: -35.778 | B51: 830.487 | C51: -35.888 | D51: 39.089
A52: -35.669 | B52: 861.206 | C52: -35.778 | D52: 39.499
A53: -35.559 | B53: 891.946 | C53: -35.669 | D53: 39.479
A54: -35.448 | B54: 922.881 | C54: -35.559 | D54: 37.722
...

Sheet Vivid V50
A1: Selador | B1: Lamp | D1: Wattage
A2: Vivid | B2: Lumileds K2 | D2: 122 | F2: Note: Owing to the variability of LEDs, output data and color matches should be viewed as approximate
F4: Note: All data taken with room temperature fixture
B5: Beam Angle | C5: Field Angle
A6: Horizontal | B6: 12.6 | C6: 24.8
B8: Accessory Lens | C8: Candela | D8: Field Lumens | E8: Beam Lumens | F8: Lens Efficiency | G8: Efficacy
B9: V50 | C9: 5400 | D9: 1100 | E9: 620 | F9: =D9/1125 -> 0.97777778 | G9: =D9/D2 -> 9.0163934
B12: For Field diameter at any distance, multiply distance by | F12: =2*TAN(C6*3.1415926535/360) -> 0.43972852
B14: For Beam diameter at any distance, multiply distance by | F14: =2*TAN(B6*3.1415926535/360) -> 0.22080206
B16: Throw Distance (ft) | C16: 10 | D16: 15 | E16: 20 | F16: 25
B17: Throw Distance (m) | C17: =C16*0.3048 -> 3.048 | D17: =D16*0.3048 -> 4.572 | E17: =E16*0.3048 -> 6.096 | F17: =F16*0.3048 -> 7.62
B18: Field Diameter (ft) | C18: =C16*F12 -> 4.3972852 | D18: =D16*F12 -> 6.5959278 | E18: =E16*F12 -> 8.7945704 | F18: =F16*F12 -> 10.993213
B19: Field Diameter (m) | C19: =C17*F12 -> 1.3402925 | D19: =D17*F12 -> 2.0104388 | E19: =E17*F12 -> 2.6805851 | F19: =F17*F12 -> 3.3507313
B20: Illuminance (fc) | C20: =C9/(C16*C16) -> 54 | D20: =C9/(D16*D16) -> 24 | E20: =C9/(E16*E16) -> 13.5 | F20: =C9/(F16*F16) -> 8.64
B21: Illuminance (lux) | C21: =C20*10.7639 -> 581.2506 | D21: =D20*10.7639 -> 258.3336 | E21: =E20*10.7639 -> 145.31265 | F21: =F20*10.7639 -> 93.000096
A24: Test Distance | B24: Iso-Illuminance Diagram grid lines
A25: 61 | B25: 10 | C25: 20 | D25: 30 | E25: 40
B26: =B25/A25 -> 0.16393443 | C26: =C25/A25 -> 0.32786885 | D26: =D25/A25 -> 0.49180328 | E26: =E25/A25 -> 0.6557377
B28: Beam Angle | C28: Field Angle
A29: Vertical | B29: 59.3 | C29: 72.3
B32: For Field diameter at any distance, multiply distance by | F32: =2*TAN(C29*3.1415926535/360) -> 1.4611002
B34: For Beam diameter at any distance, multiply distance by | F34: =2*TAN(B29*3.1415926535/360) -> 1.1384678
B36: Throw Distance (ft) | C36: =C16 -> 10 | D36: =D16 -> 15 | E36: =E16 -> 20 | F36: =F16 -> 25
B37: Throw Distance (m) | C37: =C36*0.3048 -> 3.048 | D37: =D36*0.3048 -> 4.572 | E37: =E36*0.3048 -> 6.096 | F37: =F36*0.3048 -> 7.62
B38: Field Diameter (ft) | C38: =C36*F32 -> 14.611002 | D38: =D36*F32 -> 21.916503 | E38: =E36*F32 -> 29.222004 | F38: =F36*F32 -> 36.527505
B39: Field Diameter (m) | C39: =C37*F32 -> 4.4534334 | D39: =D37*F32 -> 6.6801501 | E39: =E37*F32 -> 8.9068668 | F39: =F37*F32 -> 11.133584
B40: Illuminance (fc) | C40: =C9/(C36*C36) -> 54 | D40: =C9/(D36*D36) -> 24 | E40: =C9/(E36*E36) -> 13.5 | F40: =C9/(F36*F36) -> 8.64
B41: Illuminance (lux) | C41: =C40*10.7639 -> 581.2506 | D41: =D40*10.7639 -> 258.3336 | E41: =E40*10.7639 -> 145.31265 | F41: =F40*10.7639 -> 93.000096
B43: X | D43: Y
A44: -36.538 | B44: 0 | C44: -36.646 | D44: 524.188
A45: -36.431 | B45: 0 | C45: -36.538 | D45: 533.056
A46: -36.323 | B46: 0 | C46: -36.431 | D46: 543.392
A47: -36.214 | B47: 4.176 | C47: -36.323 | D47: 561.736
A48: -36.106 | B48: 10.74 | C48: -36.214 | D48: 582.172
A49: -35.997 | B49: 18.221 | C49: -36.106 | D49: 603.191
A50: -35.888 | B50: 25.677 | C50: -35.997 | D50: 623.273
A51: -35.778 | B51: 30.535 | C51: -35.888 | D51: 643.791
A52: -35.669 | B52: 30.729 | C52: -35.778 | D52: 665.49
A53: -35.559 | B53: 32.126 | C53: -35.669 | D53: 686.682
A54: -35.448 | B54: 33.405 | C54: -35.559 | D54: 707.195
...

Sheet Vivid H60
A1: Selador | B1: Lamp | D1: Wattage
A2: Vivid | B2: Lumileds K2 | D2: 122 | F2: Note: Owing to the variability of LEDs, output data and color matches should be viewed as approximate
