Workbook

Sheet No Lens
A2: Color Source PAR Deep Blue | B2: 43656
B4: Beam Angle | C4: Field Angle
B5: 15.3 | C5: 26.3
F6: Lens Efficiency | G6: Power Consump (Watts) | H6: Efficacy (lm/W)
A7: Mode | B7: Accessory Lens | C7: Candela | D7: Field Lumens | E7: Beam Lumens
A8: Full ON / RGB | B8: none | C8: 51093 | D8: 2775 | E8: 1742 | F8: NA | G8: 101.2 | H8: =D8/G8 -> 27.420949
A9: 3200K / RGB | B9: none | C9: 46653 | D9: 2772 | E9: 1738 | F9: NA | G9: 72.3 | H9: =D9/G9 -> 38.340249
A10: 5600K / RGB | B10: none | C10: 46273 | D10: 2723 | E10: 1706 | F10: NA | G10: 101.6 | H10: =D10/G10 -> 26.801181
A11: Red / RGB | B11: none | C11: 9817 | D11: 588 | E11: 363 | F11: NA | G11: 29.1 | H11: =D11/G11 -> 20.206186
A12: Green / RGB | B12: none | C12: 17705 | D12: 1007 | E12: 623 | F12: NA | G12: 34.3 | H12: =D12/G12 -> 29.358601
A13: Blue / RGB | B13: none | C13: 1940 | D13: 119 | E13: 75 | F13: NA | G13: 32.2 | H13: =D13/G13 -> 3.6956522
A14: Full ON / Direct | B14: none | C14: 50156 | D14: 2978 | E14: 1874 | F14: NA | G14: 108 | H14: =D14/G14 -> 27.574074
A15: Red / Direct | B15: none | C15: 9782 | D15: 586 | E15: 364 | F15: NA | G15: 28.8 | H15: =D15/G15 -> 20.347222
A16: Lime / Direct | B16: none | C16: 21673 | D16: 1296 | E16: 822 | F16: NA | G16: 22.2 | H16: =D16/G16 -> 58.378378
A17: Green / Direct | B17: none | C17: 17851 | D17: 1010 | E17: 626 | F17: NA | G17: 34.2 | H17: =D17/G17 -> 29.532164
A18: Blue / Direct | B18: none | C18: 1729 | D18: 107 | E18: 68 | F18: NA | G18: 32.3 | H18: =D18/G18 -> 3.3126935
B20: For Field diameter at any distance, multiply distance by | F20: =2*TAN(C5*3.1415926535/360) -> 0.4672548
B22: For Beam diameter at any distance, multiply distance by | F22: =2*TAN(B5*3.1415926535/360) -> 0.26863358
G23: Dist for 1.0 fc
B24: Throw Distance (ft) | C24: 10 | D24: 15 | E24: 20 | F24: 25 | G24: =SQRT(C8) -> 226.03761
B25: Throw Distance (m) | C25: =C24*0.3048 -> 3.048 | D25: =D24*0.3048 -> 4.572 | E25: =E24*0.3048 -> 6.096 | F25: =F24*0.3048 -> 7.62 | G25: =G24*0.3048 -> 68.896263
B26: Field Diameter (ft) | C26: =C24*F20 -> 4.672548 | D26: =D24*F20 -> 7.008822 | E26: =E24*F20 -> 9.3450959 | F26: =F24*F20 -> 11.68137
B27: Field Diameter (m) | C27: =C25*F20 -> 1.4241926 | D27: =D25*F20 -> 2.1362889 | E27: =E25*F20 -> 2.8483852 | F27: =F25*F20 -> 3.5604816
B28: Illuminance (fc) | C28: =C8/(C24*C24) -> 510.93 | D28: =C8/(D24*D24) -> 227.08 | E28: =C8/(E24*E24) -> 127.7325 | F28: =C8/(F24*F24) -> 81.7488
B29: Illuminance (lux) | C29: =C28*10.7639 -> 5499.5994 | D29: =D28*10.7639 -> 2444.2664 | E29: =E28*10.7639 -> 1374.8999 | F29: =F28*10.7639 -> 879.93591
A31: Test Distance | B31: Iso-Illuminance Diagram grid lines
A32: 171.25 | B32: 10 | C32: 20 | D32: 30 | E32: 40
B33: =B32/A32 -> 0.058394161 | C33: =C32/A32 -> 0.11678832 | D33: =D32/A32 -> 0.17518248 | E33: =E32/A32 -> 0.23357664
A60: Measurement: Full ON rgb mode no diffuser - Intensity
A62: Degrees | B62: (Cd)
A63: -18.95435 | B63: 0
A64: -18.9054 | B64: 0
A65: -18.85645 | B65: 0
A66: -18.8075 | B66: 0
A67: -18.75855 | B67: 0
A68: -18.7096 | B68: 0
A69: -18.66065 | B69: 0
A70: -18.6117 | B70: 0
A71: -18.56275 | B71: 0
A72: -18.5138 | B72: 0
...

Sheet VNR
A2: Color Source PAR Deep Blue | B2: 43656
B4: Beam Angle | C4: Field Angle
B5: 15.5 | C5: 27.6
F6: Lens Efficiency | G6: Power Consump (Watts) | H6: Efficacy (lm/W)
A7: Mode / Color | B7: Accessory Lens | C7: Candela | D7: Field Lumens | E7: Beam Lumens
A8: Full ON / RGB | B8: VNR | C8: ='No Lens'!C8*VNR!K8 -> 44858.862 | D8: ='No Lens'!D8*VNR!L8 -> 2596.4302 | E8: ='No Lens'!E8*VNR!M8 -> 2158 | F8: =D8/'No Lens'!D8 -> 0.93565054 | G8: 101.2 | H8: =D8/G8 -> 25.656425 | K8: 0.87798449 | L8: 0.93565054 | M8: 1.238806
A9: 3200K / RGB | B9: VNR | C9: =C8*0.96990745 -> 43508.944 | D9: =D8*0.96990745 -> 2518.297 | E9: =E8*0.96990745 -> 2093.0603 | F9: =D9/'No Lens'!D9 -> 0.90847657 | G9: 72.3 | H9: =D9/G9 -> 34.831218
A10: 5600K / RGB | B10: VNR | C10: =C8*0.955419195 -> 42859.017 | D10: =D8*0.955419195 -> 2480.6793 | E10: =E8*0.955419195 -> 2061.7946 | F10: =D10/'No Lens'!D10 -> 0.91100966 | G10: 101.6 | H10: =D10/G10 -> 24.416135
A11: Red / RGB | B11: VNR | C11: =C8*0.204137629 -> 9157.3817 | D11: =D8*0.204137629 -> 530.02911 | E11: =E8*0.204137629 -> 440.529 | F11: =D11/'No Lens'!D11 -> 0.90141006 | G11: 29.1 | H11: =D11/G11 -> 18.214059
A12: Green / RGB | B12: VNR | C12: =C8*0.355680917 -> 15955.441 | D12: =D8*0.355680917 -> 923.50069 | E12: =E8*0.355680917 -> 767.55942 | F12: =D12/'No Lens'!D12 -> 0.91708112 | G12: 34.3 | H12: =D12/G12 -> 26.924218
A13: Blue / RGB | B13: VNR | C13: =C8*0.041302273 -> 1852.7729 | D13: =D8*0.041302273 -> 107.23847 | E13: =E8*0.041302273 -> 89.130305 | F13: =D13/'No Lens'!D13 -> 0.90116362 | G13: 32.2 | H13: =D13/G13 -> 3.3303873
A14: Full ON / Direct | B14: VNR | C14: =C8*1.043529672 -> 46811.553 | D14: =D8*1.043529672 -> 2709.452 | E14: =E8*1.043529672 -> 2251.937 | F14: =D14/'No Lens'!D14 -> 0.9098227 | G14: 108 | H14: =D14/G14 -> 25.087519
A15: Red / Direct | B15: VNR | C15: =C8*0.203860398 -> 9144.9454 | D15: =D8*0.203860398 -> 529.3093 | E15: =E8*0.203860398 -> 439.93074 | F15: =D15/'No Lens'!D15 -> 0.9032582 | G15: 28.8 | H15: =D15/G15 -> 18.378795
A16: Lime / Direct | B16: VNR | C16: =C8*0.454361902 -> 20382.158 | D16: =D8*0.454361902 -> 1179.719 | E16: =E8*0.454361902 -> 980.51298 | F16: =D16/'No Lens'!D16 -> 0.910277 | G16: 22.2 | H16: =D16/G16 -> 53.140495
A17: Green / Direct | B17: VNR | C17: =C8*0.357567841 -> 16040.086 | D17: =D8*0.357567841 -> 928.39996 | E17: =E8*0.357567841 -> 771.6314 | F17: =D17/'No Lens'!D17 -> 0.91920788 | G17: 34.2 | H17: =D17/G17 -> 27.146198
A18: Blue / Direct | B18: VNR | C18: =C8*0.037144801 -> 1666.2735 | D18: =D8*0.037144801 -> 96.443885 | E18: =E8*0.037144801 -> 80.158481 | F18: =D18/'No Lens'!D18 -> 0.90134472 | G18: 32.3 | H18: =D18/G18 -> 2.9858788
B20: For Field diameter at any distance, multiply distance by | F20: =2*TAN(C5*3.1415926535/360) -> 0.49124712
B22: For Beam diameter at any distance, multiply distance by | F22: =2*TAN(B5*3.1415926535/360) -> 0.27218805
G23: Dist for 1.0 fc
B24: Throw Distance (ft) | C24: 10 | D24: 15 | E24: 20 | F24: 25 | G24: =SQRT(C8) -> 211.79911
B25: Throw Distance (m) | C25: =C24*0.3048 -> 3.048 | D25: =D24*0.3048 -> 4.572 | E25: =E24*0.3048 -> 6.096 | F25: =F24*0.3048 -> 7.62 | G25: =G24*0.3048 -> 64.556368
B26: Field Diameter (ft) | C26: =C24*F20 -> 4.9124712 | D26: =D24*F20 -> 7.3687068 | E26: =E24*F20 -> 9.8249423 | F26: =F24*F20 -> 12.281178
B27: Field Diameter (m) | C27: =C25*F20 -> 1.4973212 | D27: =D25*F20 -> 2.2459818 | E27: =E25*F20 -> 2.9946424 | F27: =F25*F20 -> 3.743303
B28: Illuminance (fc) | C28: =C8/(C24*C24) -> 448.58862 | D28: =C8/(D24*D24) -> 199.37272 | E28: =C8/(E24*E24) -> 112.14715 | F28: =C8/(F24*F24) -> 71.774179
B29: Illuminance (lux) | C29: =C28*10.7639 -> 4828.563 | D29: =D28*10.7639 -> 2146.028 | E29: =E28*10.7639 -> 1207.1408 | F29: =F28*10.7639 -> 772.57008
A31: Test Distance | B31: Iso-Illuminance Diagram grid lines
A32: 162.75 | B32: 10 | C32: 20 | D32: 30 | E32: 40
B33: =B32/A32 -> 0.061443932 | C33: =C32/A32 -> 0.12288786 | D33: =D32/A32 -> 0.1843318 | E33: =E32/A32 -> 0.24577573
A60: Measurement: VNR Full ON rgb mode - Intensity
A62: Degrees | B62: (Cd)
A63: -19.8689 | B63: 0
A64: -19.81759 | B64: 0
A65: -19.76628 | B65: 0
A66: -19.71496 | B66: 0
A67: -19.66365 | B67: 0
A68: -19.61234 | B68: 0
A69: -19.56103 | B69: 0
A70: -19.50972 | B70: 0
A71: -19.45841 | B71: 0
A72: -19.4071 | B72: 0
...

Sheet VNL
A2: Color Source PAR Deep Blue | B2: 43656
B4: Beam Angle | C4: Field Angle
A5: Horizontal | B5: 28.4 | C5: 43.5
F6: Lens Efficiency | G6: Power Consump (Watts) | H6: Efficacy (lm/W)
A7: Mode | B7: Accessory Lens | C7: Candela | D7: Field Lumens | E7: Beam Lumens
A8: Full ON / RGB | B8: VNL | C8: ='No Lens'!C8*VNL!K8 -> 26422.662 | D8: ='No Lens'!D8*VNL!L8 -> 2767.1794 | E8: ='No Lens'!E8*VNL!M8 -> 1653.0526 | F8: =D8/'No Lens'!D8 -> 0.99718178 | G8: 101.2 | H8: =D8/G8 -> 27.34367 | K8: 0.51714837 | L8: 0.99718178 | M8: 0.94893951
A9: 3200K / RGB | B9: VNL | C9: =C8*0.96990745 -> 25627.537 | D9: =D8*0.96990745 -> 2683.9079 | E9: =E8*0.96990745 -> 1603.3081 | F9: =D9/'No Lens'!D9 -> 0.96822076 | G9: 72.3 | H9: =D9/G9 -> 37.121825
A10: 5600K / RGB | B10: VNL | C10: =C8*0.955419195 -> 25244.718 | D10: =D8*0.955419195 -> 2643.8163 | E10: =E8*0.955419195 -> 1579.3582 | F10: =D10/'No Lens'!D10 -> 0.97092043 | G10: 101.6 | H10: =D10/G10 -> 26.021814
A11: Red / RGB | B11: VNL | C11: =C8*0.204137629 -> 5393.8595 | D11: =D8*0.204137629 -> 564.88545 | E11: =E8*0.204137629 -> 337.45024 | F11: =D11/'No Lens'!D11 -> 0.96068954 | G11: 29.1 | H11: =D11/G11 -> 19.411871
A12: Green / RGB | B12: VNL | C12: =C8*0.355680917 -> 9398.0366 | D12: =D8*0.355680917 -> 984.23292 | E12: =E8*0.355680917 -> 587.95928 | F12: =D12/'No Lens'!D12 -> 0.97739118 | G12: 34.3 | H12: =D12/G12 -> 28.694837
A13: Blue / RGB | B13: VNL | C13: =C8*0.041302273 -> 1091.316 | D13: =D8*0.041302273 -> 114.2908 | E13: =E8*0.041302273 -> 68.274831 | F13: =D13/'No Lens'!D13 -> 0.96042689 | G13: 32.2 | H13: =D13/G13 -> 3.5494037
A14: Full ON / Direct | B14: VNL | C14: =C8*1.043529672 -> 27572.832 | D14: =D8*1.043529672 -> 2887.6338 | E14: =E8*1.043529672 -> 1725.0095 | F14: =D14/'No Lens'!D14 -> 0.96965542 | G14: 108 | H14: =D14/G14 -> 26.73735
A15: Red / Direct | B15: VNL | C15: =C8*0.203860398 -> 5386.5344 | D15: =D8*0.203860398 -> 564.1183 | E15: =E8*0.203860398 -> 336.99197 | F15: =D15/'No Lens'!D15 -> 0.96265921 | G15: 28.8 | H15: =D15/G15 -> 19.587441
A16: Lime / Direct | B16: VNL | C16: =C8*0.454361902 -> 12005.451 | D16: =D8*0.454361902 -> 1257.3009 | E16: =E8*0.454361902 -> 751.08414 | F16: =D16/'No Lens'!D16 -> 0.97013959 | G16: 22.2 | H16: =D16/G16 -> 56.635176
A17: Green / Direct | B17: VNL | C17: =C8*0.357567841 -> 9447.8942 | D17: =D8*0.357567841 -> 989.45437 | E17: =E8*0.357567841 -> 591.07846 | F17: =D17/'No Lens'!D17 -> 0.9796578 | G17: 34.2 | H17: =D17/G17 -> 28.931414
A18: Blue / Direct | B18: VNL | C18: =C8*0.037144801 -> 981.46452 | D18: =D8*0.037144801 -> 102.78633 | E18: =E8*0.037144801 -> 61.402311 | F18: =D18/'No Lens'!D18 -> 0.9606199 | G18: 32.3 | H18: =D18/G18 -> 3.1822393
B20: For Field diameter at any distance, multiply distance by | F20: =2*TAN(C5*3.1415926535/360) -> 0.79791909
B22: For Beam diameter at any distance, multiply distance by | F22: =2*TAN(B5*3.1415926535/360) -> 0.5060778
G23: Dist for 1.0 fc
B24: Throw Distance (ft) | C24: 10 | D24: 15 | E24: 20 | F24: 25 | G24: =SQRT(C8) -> 162.55049
B25: Throw Distance (m) | C25: =C24*0.3048 -> 3.048 | D25: =D24*0.3048 -> 4.572 | E25: =E24*0.3048 -> 6.096 | F25: =F24*0.3048 -> 7.62 | G25: =G24*0.3048 -> 49.545389
B26: Field Diameter (ft) | C26: =C24*F20 -> 7.9791909 | D26: =D24*F20 -> 11.968786 | E26: =E24*F20 -> 15.958382 | F26: =F24*F20 -> 19.947977
B27: Field Diameter (m) | C27: =C25*F20 -> 2.4320574 | D27: =D25*F20 -> 3.6480861 | E27: =E25*F20 -> 4.8641148 | F27: =F25*F20 -> 6.0801435
B28: Illuminance (fc) | C28: =C8/(C24*C24) -> 264.22662 | D28: =C8/(D24*D24) -> 117.43405 | E28: =C8/(E24*E24) -> 66.056655 | F28: =C8/(F24*F24) -> 42.276259
B29: Illuminance (lux) | C29: =C28*10.7639 -> 2844.1089 | D29: =D28*10.7639 -> 1264.0484 | E29: =E28*10.7639 -> 711.02723 | F29: =F28*10.7639 -> 455.05742
B31: Beam Angle | C31: Field Angle
A32: Vertical | B32: 14.9 | C32: 29.2
B34: For Field height at any distance, multiply distance by | F34: =2*TAN(C32*3.1415926535/360) -> 0.52096098
B36: For Beam height at any distance, multiply distance by | F36: =2*TAN(B32*3.1415926535/360) -> 0.26152962
A38: Test Distance | B38: Iso-Illuminance Diagram grid lines
A39: 91.75 | B39: 10 | C39: 20 | D39: 30 | E39: 40 | F39: 50
B40: =B39/A39 -> 0.10899183 | C40: =C39/A39 -> 0.21798365 | D40: =D39/A39 -> 0.32697548 | E40: =E39/A39 -> 0.4359673 | F40: =F39/A39 -> 0.54495913
A46: Measurement: VNL rgb mode - Intensity
A48: Degrees | B48: (Cd)
A49: -32.66718 | B49: 0
A50: -32.61562 | B50: 0
A51: -32.56407 | B51: 0
A52: -32.51251 | B52: 0
A53: -32.46096 | B53: 0
A54: -32.4094 | B54: 0
...

Sheet NR
A2: Color Source PAR Deep Blue | B2: 43656
B4: Beam Angle | C4: Field Angle
B5: 16.8 | C5: 31.8
F6: Lens Efficiency | G6: Power Consump (Watts) | H6: Efficacy (lm/W)
A7: Mode | B7: Accessory Lens | C7: Candela | D7: Field Lumens | E7: Beam Lumens
A8: Full ON / RGB | B8: NR | C8: ='No Lens'!C8*NR!K8 -> 35088.756 | D8: ='No Lens'!D8*NR!L8 -> 2524.7417 | E8: ='No Lens'!E8*NR!M8 -> 1336.9474 | F8: =D8/'No Lens'!D8 -> 0.90981682 | G8: 101.2 | H8: =D8/G8 -> 24.94804 | K8: 0.6867625 | L8: 0.90981682 | M8: 0.7674784
A9: 3200K / RGB | B9: NR | C9: =C8*0.96990745 -> 34032.846 | D9: =D8*0.96990745 -> 2448.7657 | E9: =E8*0.96990745 -> 1296.7152 | F9: =D9/'No Lens'!D9 -> 0.88339313 | G9: 72.3 | H9: =D9/G9 -> 33.869512
A10: 5600K / RGB | B10: NR | C10: =C8*0.955419195 -> 33524.471 | D10: =D8*0.955419195 -> 2412.1866 | E10: =E8*0.955419195 -> 1277.3452 | F10: =D10/'No Lens'!D10 -> 0.88585628 | G10: 101.6 | H10: =D10/G10 -> 23.741995
A11: Red / RGB | B11: NR | C11: =C8*0.204137629 -> 7162.9355 | D11: =D8*0.204137629 -> 515.39478 | E11: =E8*0.204137629 -> 272.92127 | F11: =D11/'No Lens'!D11 -> 0.87652173 | G11: 29.1 | H11: =D11/G11 -> 17.711161
A12: Green / RGB | B12: NR | C12: =C8*0.355680917 -> 12480.401 | D12: =D8*0.355680917 -> 898.00243 | E12: =E8*0.355680917 -> 475.52667 | F12: =D12/'No Lens'!D12 -> 0.89176011 | G12: 34.3 | H12: =D12/G12 -> 26.180829
A13: Blue / RGB | B13: NR | C13: =C8*0.041302273 -> 1449.2454 | D13: =D8*0.041302273 -> 104.27757 | E13: =E8*0.041302273 -> 55.218965 | F13: =D13/'No Lens'!D13 -> 0.8762821 | G13: 32.2 | H13: =D13/G13 -> 3.2384338
A14: Full ON / Direct | B14: NR | C14: =C8*1.043529672 -> 36616.158 | D14: =D8*1.043529672 -> 2634.6428 | E14: =E8*1.043529672 -> 1395.1442 | F14: =D14/'No Lens'!D14 -> 0.8847021 | G14: 108 | H14: =D14/G14 -> 24.394841
A15: Red / Direct | B15: NR | C15: =C8*0.203860398 -> 7153.2078 | D15: =D8*0.203860398 -> 514.69484 | E15: =E8*0.203860398 -> 272.55062 | F15: =D15/'No Lens'!D15 -> 0.87831884 | G15: 28.8 | H15: =D15/G15 -> 17.871349
A16: Lime / Direct | B16: NR | C16: =C8*0.454361902 -> 15942.994 | D16: =D8*0.454361902 -> 1147.1464 | E16: =E8*0.454361902 -> 607.45795 | F16: =D16/'No Lens'!D16 -> 0.88514385 | G16: 22.2 | H16: =D16/G16 -> 51.673262
A17: Green / Direct | B17: NR | C17: =C8*0.357567841 -> 12546.611 | D17: =D8*0.357567841 -> 902.76643 | E17: =E8*0.357567841 -> 478.04938 | F17: =D17/'No Lens'!D17 -> 0.89382814 | G17: 34.2 | H17: =D17/G17 -> 26.396679
A18: Blue / Direct | B18: NR | C18: =C8*0.037144801 -> 1303.3649 | D18: =D8*0.037144801 -> 93.781027 | E18: =E8*0.037144801 -> 49.660644 | F18: =D18/'No Lens'!D18 -> 0.87645819 | G18: 32.3 | H18: =D18/G18 -> 2.9034374
B20: For Field diameter at any distance, multiply distance by | F20: =2*TAN(C5*3.1415926535/360) -> 0.56971499
B22: For Beam diameter at any distance, multiply distance by | F22: =2*TAN(B5*3.1415926535/360) -> 0.29533431
G23: Dist for 1.0 fc
B24: Throw Distance (ft) | C24: 10 | D24: 15 | E24: 20 | F24: 25 | G24: =SQRT(C8) -> 187.31993
B25: Throw Distance (m) | C25: =C24*0.3048 -> 3.048 | D25: =D24*0.3048 -> 4.572 | E25: =E24*0.3048 -> 6.096 | F25: =F24*0.3048 -> 7.62 | G25: =G24*0.3048 -> 57.095115
B26: Field Diameter (ft) | C26: =C24*F20 -> 5.6971499 | D26: =D24*F20 -> 8.5457248 | E26: =E24*F20 -> 11.3943 | F26: =F24*F20 -> 14.242875
B27: Field Diameter (m) | C27: =C25*F20 -> 1.7364913 | D27: =D25*F20 -> 2.6047369 | E27: =E25*F20 -> 3.4729826 | F27: =F25*F20 -> 4.3412282
B28: Illuminance (fc) | C28: =C8/(C24*C24) -> 350.88756 | D28: =C8/(D24*D24) -> 155.95003 | E28: =C8/(E24*E24) -> 87.721891 | F28: =C8/(F24*F24) -> 56.14201
B29: Illuminance (lux) | C29: =C28*10.7639 -> 3776.9186 | D29: =D28*10.7639 -> 1678.6305 | E29: =E28*10.7639 -> 944.22966 | F29: =F28*10.7639 -> 604.30698
A31: Test Distance | B31: Iso-Illuminance Diagram grid lines
A32: 140.25 | B32: 10 | C32: 20 | D32: 30 | E32: 40
B33: =B32/A32 -> 0.071301248 | C33: =C32/A32 -> 0.1426025 | D33: =D32/A32 -> 0.21390374 | E33: =E32/A32 -> 0.28520499
A60: Measurement: NR rgb mode - Intensity
A62: Degrees | B62: (Cd)
A63: -22.75382 | B63: 0 | C63: =B63/21900 -> 0
A64: -22.70485 | B64: 0 | C64: =B64/21900 -> 0
A65: -22.65588 | B65: 0 | C65: =B65/21900 -> 0
A66: -22.60691 | B66: 0 | C66: =B66/21900 -> 0
A67: -22.55795 | B67: 0 | C67: =B67/21900 -> 0
A68: -22.50898 | B68: 0 | C68: =B68/21900 -> 0
A69: -22.46001 | B69: 0 | C69: =B69/21900 -> 0
A70: -22.41104 | B70: 0 | C70: =B70/21900 -> 0
A71: -22.36207 | B71: 0 | C71: =B71/21900 -> 0
A72: -22.3131 | B72: 0 | C72: =B72/21900 -> 0
...

Sheet NL
A2: Color Source PAR Deep Blue | B2: 43656
B4: Beam Angle | C4: Field Angle
A5: Horizontal | B5: 27.6 | C5: 42.4
F6: Lens Efficiency | G6: Power Consump (Watts) | H6: Efficacy (lm/W)
A7: Mode | B7: Accessory Lens | C7: Candela | D7: Field Lumens | E7: Beam Lumens
A8: Full ON / RGB | B8: NL | C8: ='No Lens'!C8*NL!K8 -> 26505.658 | D8: ='No Lens'!D8*NL!L8 -> 2705.9183 | E8: ='No Lens'!E8*NL!M8 -> 1613.3684 | F8: =D8/'No Lens'!D8 -> 0.97510568 | G8: 101.2 | H8: =D8/G8 -> 26.738323 | K8: 0.5187728 | L8: 0.97510568 | M8: 0.92615868
A9: 3200K / RGB | B9: NL | C9: =C8*0.96990745 -> 25708.036 | D9: =D8*0.96990745 -> 2624.4903 | E9: =E8*0.96990745 -> 1564.8181 | F9: =D9/'No Lens'!D9 -> 0.94678582 | G9: 72.3 | H9: =D9/G9 -> 36.300004
A10: 5600K / RGB | B10: NL | C10: =C8*0.955419195 -> 25324.015 | D10: =D8*0.955419195 -> 2585.2863 | E10: =E8*0.955419195 -> 1541.4432 | F10: =D10/'No Lens'!D10 -> 0.94942573 | G10: 101.6 | H10: =D10/G10 -> 25.445731
A11: Red / RGB | B11: NL | C11: =C8*0.204137629 -> 5410.8023 | D11: =D8*0.204137629 -> 552.37974 | E11: =E8*0.204137629 -> 329.3492 | F11: =D11/'No Lens'!D11 -> 0.93942133 | G11: 29.1 | H11: =D11/G11 -> 18.982122
A12: Green / RGB | B12: NL | C12: =C8*0.355680917 -> 9427.5569 | D12: =D8*0.355680917 -> 962.44349 | E12: =E8*0.355680917 -> 573.84436 | F12: =D12/'No Lens'!D12 -> 0.95575322 | G12: 34.3 | H12: =D12/G12 -> 28.059577
A13: Blue / RGB | B13: NL | C13: =C8*0.041302273 -> 1094.7439 | D13: =D8*0.041302273 -> 111.76058 | E13: =E8*0.041302273 -> 66.635783 | F13: =D13/'No Lens'!D13 -> 0.9391645 | G13: 32.2 | H13: =D13/G13 -> 3.4708253
A14: Full ON / Direct | B14: NL | C14: =C8*1.043529672 -> 27659.441 | D14: =D8*1.043529672 -> 2823.706 | E14: =E8*1.043529672 -> 1683.5978 | F14: =D14/'No Lens'!D14 -> 0.94818872 | G14: 108 | H14: =D14/G14 -> 26.145426
A15: Red / Direct | B15: NL | C15: =C8*0.203860398 -> 5403.4541 | D15: =D8*0.203860398 -> 551.62958 | E15: =E8*0.203860398 -> 328.90193 | F15: =D15/'No Lens'!D15 -> 0.9413474 | G15: 28.8 | H15: =D15/G15 -> 19.153805
A16: Lime / Direct | B16: NL | C16: =C8*0.454361902 -> 12043.161 | D16: =D8*0.454361902 -> 1229.4662 | E16: =E8*0.454361902 -> 733.05314 | F16: =D16/'No Lens'!D16 -> 0.94866217 | G16: 22.2 | H16: =D16/G16 -> 55.381359
A17: Green / Direct | B17: NL | C17: =C8*0.357567841 -> 9477.5711 | D17: =D8*0.357567841 -> 967.54935 | E17: =E8*0.357567841 -> 576.88866 | F17: =D17/'No Lens'!D17 -> 0.95796966 | G17: 34.2 | H17: =D17/G17 -> 28.290917
A18: Blue / Direct | B18: NL | C18: =C8*0.037144801 -> 984.54741 | D18: =D8*0.037144801 -> 100.5108 | E18: =E8*0.037144801 -> 59.928249 | F18: =D18/'No Lens'!D18 -> 0.93935323 | G18: 32.3 | H18: =D18/G18 -> 3.1117893
B20: For Field diameter at any distance, multiply distance by | F20: =2*TAN(C5*3.1415926535/360) -> 0.77574888
B22: For Beam diameter at any distance, multiply distance by | F22: =2*TAN(B5*3.1415926535/360) -> 0.49124712
G23: Dist for 1.0 fc
B24: Throw Distance (ft) | C24: 10 | D24: 15 | E24: 20 | F24: 25 | G24: =SQRT(C8) -> 162.80558
B25: Throw Distance (m) | C25: =C24*0.3048 -> 3.048 | D25: =D24*0.3048 -> 4.572 | E25: =E24*0.3048 -> 6.096 | F25: =F24*0.3048 -> 7.62 | G25: =G24*0.3048 -> 49.623142
B26: Field Diameter (ft) | C26: =C24*F20 -> 7.7574888 | D26: =D24*F20 -> 11.636233 | E26: =E24*F20 -> 15.514978 | F26: =F24*F20 -> 19.393722
B27: Field Diameter (m) | C27: =C25*F20 -> 2.3644826 | D27: =D25*F20 -> 3.5467239 | E27: =E25*F20 -> 4.7289651 | F27: =F25*F20 -> 5.9112064
B28: Illuminance (fc) | C28: =C8/(C24*C24) -> 265.05658 | D28: =C8/(D24*D24) -> 117.80293 | E28: =C8/(E24*E24) -> 66.264146 | F28: =C8/(F24*F24) -> 42.409054
B29: Illuminance (lux) | C29: =C28*10.7639 -> 2853.0426 | D29: =D28*10.7639 -> 1268.0189 | E29: =E28*10.7639 -> 713.26064 | F29: =F28*10.7639 -> 456.48681
B31: Beam Angle | C31: Field Angle
A32: Vertical | B32: 14.8 | C32: 29.5
B34: For Field height at any distance, multiply distance by | F34: =2*TAN(C32*3.1415926535/360) -> 0.52655606
B36: For Beam height at any distance, multiply distance by | F36: =2*TAN(B32*3.1415926535/360) -> 0.25975465
A38: Test Distance | B38: Iso-Illuminance Diagram grid lines
A39: 91.75 | B39: 10 | C39: 20 | D39: 30 | E39: 40 | F39: 50
B40: =B39/A39 -> 0.10899183 | C40: =C39/A39 -> 0.21798365 | D40: =D39/A39 -> 0.32697548 | E40: =E39/A39 -> 0.4359673 | F40: =F39/A39 -> 0.54495913
A46: Measurement: NL rgb mode - Intensity - Luminance Scaled 0.1
A48: Degrees | B48: (Cd)
A49: -32.66718 | B49: 0
A50: -32.61562 | B50: 0
A51: -32.56407 | B51: 0
A52: -32.51251 | B52: 0
A53: -32.46096 | B53: 0
A54: -32.4094 | B54: 0
...

Sheet NO
A2: Color Source PAR Deep Blue | B2: 43656
B4: Beam Angle | C4: Field Angle
A5: Horizontal | B5: 22.4 | C5: 43.9
F6: Lens Efficiency | G6: Power Consump (Watts) | H6: Efficacy (lm/W)
A7: Mode | B7: Accessory Lens | C7: Candela | D7: Field Lumens | E7: Beam Lumens
A8: Full ON / RGB | B8: NO | C8: ='No Lens'!C8*NO!K8 -> 30533.341 | D8: ='No Lens'!D8*NO!L8 -> 2648.5674 | E8: ='No Lens'!E8*NO!M8 -> 1395.7895 | F8: =D8/'No Lens'!D8 -> 0.9544387 | G8: 101.2 | H8: =D8/G8 -> 26.171615 | K8: 0.59760321 | L8: 0.9544387 | M8: 0.80125687
A9: 3200K / RGB | B9: NO | C9: =C8*0.96990745 -> 29614.515 | D9: =D8*0.96990745 -> 2568.8653 | E9: =E8*0.96990745 -> 1353.7866 | F9: =D9/'No Lens'!D9 -> 0.92671907 | G9: 72.3 | H9: =D9/G9 -> 35.53064
A10: 5600K / RGB | B10: NO | C10: =C8*0.955419195 -> 29172.14 | D10: =D8*0.955419195 -> 2530.4921 | E10: =E8*0.955419195 -> 1333.5641 | F10: =D10/'No Lens'!D10 -> 0.92930302 | G10: 101.6 | H10: =D10/G10 -> 24.906419
A11: Red / RGB | B11: NO | C11: =C8*0.204137629 -> 6233.0038 | D11: =D8*0.204137629 -> 540.67227 | E11: =E8*0.204137629 -> 284.93315 | F11: =D11/'No Lens'!D11 -> 0.91951066 | G11: 29.1 | H11: =D11/G11 -> 18.579803
A12: Green / RGB | B12: NO | C12: =C8*0.355680917 -> 10860.127 | D12: =D8*0.355680917 -> 942.04488 | E12: =E8*0.355680917 -> 496.45568 | F12: =D12/'No Lens'!D12 -> 0.93549641 | G12: 34.3 | H12: =D12/G12 -> 27.464865
A13: Blue / RGB | B13: NO | C13: =C8*0.041302273 -> 1261.0964 | D13: =D8*0.041302273 -> 109.39185 | E13: =E8*0.041302273 -> 57.649278 | F13: =D13/'No Lens'!D13 -> 0.91925928 | G13: 32.2 | H13: =D13/G13 -> 3.3972625
A14: Full ON / Direct | B14: NO | C14: =C8*1.043529672 -> 31862.447 | D14: =D8*1.043529672 -> 2763.8587 | E14: =E8*1.043529672 -> 1456.5477 | F14: =D14/'No Lens'!D14 -> 0.92809223 | G14: 108 | H14: =D14/G14 -> 25.591284
A15: Red / Direct | B15: NO | C15: =C8*0.203860398 -> 6224.539 | D15: =D8*0.203860398 -> 539.938 | E15: =E8*0.203860398 -> 284.5462 | F15: =D15/'No Lens'!D15 -> 0.92139591 | G15: 28.8 | H15: =D15/G15 -> 18.747847
A16: Lime / Direct | B16: NO | C16: =C8*0.454361902 -> 13873.187 | D16: =D8*0.454361902 -> 1203.4081 | E16: =E8*0.454361902 -> 634.19356 | F16: =D16/'No Lens'!D16 -> 0.92855565 | G16: 22.2 | H16: =D16/G16 -> 54.207573
A17: Green / Direct | B17: NO | C17: =C8*0.357567841 -> 10917.741 | D17: =D8*0.357567841 -> 947.04253 | E17: =E8*0.357567841 -> 499.08943 | F17: =D17/'No Lens'!D17 -> 0.93766587 | G17: 34.2 | H17: =D17/G17 -> 27.691302
A18: Blue / Direct | B18: NO | C18: =C8*0.037144801 -> 1134.1549 | D18: =D8*0.037144801 -> 98.380509 | E18: =E8*0.037144801 -> 51.846322 | F18: =D18/'No Lens'!D18 -> 0.91944401 | G18: 32.3 | H18: =D18/G18 -> 3.0458362
B20: For Field diameter at any distance, multiply distance by | F20: =2*TAN(C5*3.1415926535/360) -> 0.80602293
B22: For Beam diameter at any distance, multiply distance by | F22: =2*TAN(B5*3.1415926535/360) -> 0.39601066
G23: Dist for 1.0 fc
B24: Throw Distance (ft) | C24: 10 | D24: 15 | E24: 20 | F24: 25 | G24: =SQRT(C8) -> 174.73792
B25: Throw Distance (m) | C25: =C24*0.3048 -> 3.048 | D25: =D24*0.3048 -> 4.572 | E25: =E24*0.3048 -> 6.096 | F25: =F24*0.3048 -> 7.62 | G25: =G24*0.3048 -> 53.260118
B26: Field Diameter (ft) | C26: =C24*F20 -> 8.0602293 | D26: =D24*F20 -> 12.090344 | E26: =E24*F20 -> 16.120459 | F26: =F24*F20 -> 20.150573
B27: Field Diameter (m) | C27: =C25*F20 -> 2.4567579 | D27: =D25*F20 -> 3.6851369 | E27: =E25*F20 -> 4.9135158 | F27: =F25*F20 -> 6.1418948
B28: Illuminance (fc) | C28: =C8/(C24*C24) -> 305.33341 | D28: =C8/(D24*D24) -> 135.70374 | E28: =C8/(E24*E24) -> 76.333352 | F28: =C8/(F24*F24) -> 48.853345
B29: Illuminance (lux) | C29: =C28*10.7639 -> 3286.5783 | D29: =D28*10.7639 -> 1460.7015 | E29: =E28*10.7639 -> 821.64457 | F29: =F28*10.7639 -> 525.85253
B31: Beam Angle | C31: Field Angle
A32: Vertical | B32: 15 | C32: 28.5
B34: For Field height at any distance, multiply distance by | F34: =2*TAN(C32*3.1415926535/360) -> 0.50793529
B36: For Beam height at any distance, multiply distance by | F36: =2*TAN(B32*3.1415926535/360) -> 0.263305
A38: Test Distance | B38: Iso-Illuminance Diagram grid lines
A39: 91.75 | B39: 10 | C39: 20 | D39: 30 | E39: 40 | F39: 50
B40: =B39/A39 -> 0.10899183 | C40: =C39/A39 -> 0.21798365 | D40: =D39/A39 -> 0.32697548 | E40: =E39/A39 -> 0.4359673 | F40: =F39/A39 -> 0.54495913
A46: Measurement: NO rgb mode - Intensity
A48: Degrees | B48: (Cd)
A49: -32.66718 | B49: 0
A50: -32.61562 | B50: 0
A51: -32.56407 | B51: 0
A52: -32.51251 | B52: 0
A53: -32.46096 | B53: 0
A54: -32.4094 | B54: 0
...

Sheet MR
A2: Color Source PAR Deep Blue | B2: 43656
B4: Beam Angle | C4: Field Angle
B5: 25.1 | C5: 50
F6: Lens Efficiency | G6: Power Consump (Watts) | H6: Efficacy (lm/W)
A7: Mode | B7: Accessory Lens | C7: Candela | D7: Field Lumens | E7: Beam Lumens
A8: Full ON / RGB | B8: MR | C8: ='No Lens'!C8*MR!K8 -> 15233.785 | D8: ='No Lens'!D8*MR!L8 -> 2507.7971 | E8: ='No Lens'!E8*MR!M8 -> 1186.4211 | F8: =D8/'No Lens'!D8 -> 0.90371066 | G8: 101.2 | H8: =D8/G8 -> 24.780604 | K8: 0.29815797 | L8: 0.90371066 | M8: 0.68106834
A9: 3200K / RGB | B9: MR | C9: =C8*0.96990745 -> 14775.362 | D9: =D8*0.96990745 -> 2432.3311 | E9: =E8*0.96990745 -> 1150.7186 | F9: =D9/'No Lens'!D9 -> 0.87746431 | G9: 72.3 | H9: =D9/G9 -> 33.6422
A10: 5600K / RGB | B10: MR | C10: =C8*0.955419195 -> 14554.651 | D10: =D8*0.955419195 -> 2395.9975 | E10: =E8*0.955419195 -> 1133.5294 | F10: =D10/'No Lens'!D10 -> 0.87991093 | G10: 101.6 | H10: =D10/G10 -> 23.582652
A11: Red / RGB | B11: MR | C11: =C8*0.204137629 -> 3109.7888 | D11: =D8*0.204137629 -> 511.93575 | E11: =E8*0.204137629 -> 242.19318 | F11: =D11/'No Lens'!D11 -> 0.87063903 | G11: 29.1 | H11: =D11/G11 -> 17.592294
A12: Green / RGB | B12: MR | C12: =C8*0.355680917 -> 5418.3666 | D12: =D8*0.355680917 -> 891.97557 | E12: =E8*0.355680917 -> 421.98733 | F12: =D12/'No Lens'!D12 -> 0.88577514 | G12: 34.3 | H12: =D12/G12 -> 26.005119
A13: Blue / RGB | B13: MR | C13: =C8*0.041302273 -> 629.18995 | D13: =D8*0.041302273 -> 103.57772 | E13: =E8*0.041302273 -> 49.001886 | F13: =D13/'No Lens'!D13 -> 0.87040101 | G13: 32.2 | H13: =D13/G13 -> 3.2166994
A14: Full ON / Direct | B14: MR | C14: =C8*1.043529672 -> 15896.907 | D14: =D8*1.043529672 -> 2616.9607 | E14: =E8*1.043529672 -> 1238.0656 | F14: =D14/'No Lens'!D14 -> 0.8787645 | G14: 108 | H14: =D14/G14 -> 24.231117
A15: Red / Direct | B15: MR | C15: =C8*0.203860398 -> 3105.5655 | D15: =D8*0.203860398 -> 511.24051 | E15: =E8*0.203860398 -> 241.86427 | F15: =D15/'No Lens'!D15 -> 0.87242408 | G15: 28.8 | H15: =D15/G15 -> 17.751407
A16: Lime / Direct | B16: MR | C16: =C8*0.454361902 -> 6921.6515 | D16: =D8*0.454361902 -> 1139.4475 | E16: =E8*0.454361902 -> 539.06453 | F16: =D16/'No Lens'!D16 -> 0.87920328 | G16: 22.2 | H16: =D16/G16 -> 51.326462
A17: Green / Direct | B17: MR | C17: =C8*0.357567841 -> 5447.1116 | D17: =D8*0.357567841 -> 896.70759 | E17: =E8*0.357567841 -> 424.22601 | F17: =D17/'No Lens'!D17 -> 0.8878293 | G17: 34.2 | H17: =D17/G17 -> 26.21952
A18: Blue / Direct | B18: MR | C18: =C8*0.037144801 -> 565.85591 | D18: =D8*0.037144801 -> 93.151624 | E18: =E8*0.037144801 -> 44.069374 | F18: =D18/'No Lens'!D18 -> 0.87057592 | G18: 32.3 | H18: =D18/G18 -> 2.8839512
B20: For Field diameter at any distance, multiply distance by | F20: =2*TAN(C5*3.1415926535/360) -> 0.93261532
B22: For Beam diameter at any distance, multiply distance by | F22: =2*TAN(B5*3.1415926535/360) -> 0.44522079
G23: Dist for 1.0 fc
B24: Throw Distance (ft) | C24: 10 | D24: 15 | E24: 20 | F24: 25 | G24: =SQRT(C8) -> 123.42522
B25: Throw Distance (m) | C25: =C24*0.3048 -> 3.048 | D25: =D24*0.3048 -> 4.572 | E25: =E24*0.3048 -> 6.096 | F25: =F24*0.3048 -> 7.62 | G25: =G24*0.3048 -> 37.620007
B26: Field Diameter (ft) | C26: =C24*F20 -> 9.3261532 | D26: =D24*F20 -> 13.98923 | E26: =E24*F20 -> 18.652306 | F26: =F24*F20 -> 23.315383
B27: Field Diameter (m) | C27: =C25*F20 -> 2.8426115 | D27: =D25*F20 -> 4.2639172 | E27: =E25*F20 -> 5.685223 | F27: =F25*F20 -> 7.1065287
B28: Illuminance (fc) | C28: =C8/(C24*C24) -> 152.33785 | D28: =C8/(D24*D24) -> 67.705711 | E28: =C8/(E24*E24) -> 38.084463 | F28: =C8/(F24*F24) -> 24.374056
B29: Illuminance (lux) | C29: =C28*10.7639 -> 1639.7494 | D29: =D28*10.7639 -> 728.77751 | E29: =E28*10.7639 -> 409.93735 | F29: =F28*10.7639 -> 262.3599
A31: Test Distance | B31: Iso-Illuminance Diagram grid lines
A32: 91.75 | B32: 10 | C32: 20 | D32: 30 | E32: 40
B33: =B32/A32 -> 0.10899183 | C33: =C32/A32 -> 0.21798365 | D33: =D32/A32 -> 0.32697548 | E33: =E32/A32 -> 0.4359673
A60: Measurement: MR rgb mode - Intensity
A62: Degrees | B62: (Cd)
A63: -32.66718 | B63: 0
A64: -32.61562 | B64: 0
A65: -32.56407 | B65: 0
A66: -32.51251 | B66: 0
A67: -32.46096 | B67: 0
A68: -32.4094 | B68: 0
A69: -32.35785 | B69: 0
A70: -32.30629 | B70: 0
A71: -32.25474 | B71: 0
A72: -32.20318 | B72: 0
...

Sheet MO
A2: Color Source PAR Deep Blue | B2: 43656
B4: Beam Angle | C4: Field Angle
A5: Horizontal | B5: 30.2 | C5: 60.6
F6: Lens Efficiency | G6: Power Consump (Watts) | H6: Efficacy (lm/W)
A7: Mode | B7: Accessory Lens | C7: Candela | D7: Field Lumens | E7: Beam Lumens
A8: Full ON / RGB | B8: MO | C8: ='No Lens'!C8*MO!K8 -> 20158.77 | D8: ='No Lens'!D8*MO!L8 -> 2542.9897 | E8: ='No Lens'!E8*MO!M8 -> 1257.5789 | F8: =D8/'No Lens'!D8 -> 0.91639267 | G8: 101.2 | H8: =D8/G8 -> 25.128356 | K8: 0.39455053 | L8: 0.91639267 | M8: 0.72191673
A9: 3200K / RGB | B9: MO | C9: =C8*0.96990745 -> 19552.141 | D9: =D8*0.96990745 -> 2466.4646 | E9: =E8*0.96990745 -> 1219.7352 | F9: =D9/'No Lens'!D9 -> 0.889778 | G9: 72.3 | H9: =D9/G9 -> 34.11431
A10: 5600K / RGB | B10: MO | C10: =C8*0.955419195 -> 19260.076 | D10: =D8*0.955419195 -> 2429.6211 | E10: =E8*0.955419195 -> 1201.5151 | F10: =D10/'No Lens'!D10 -> 0.89225896 | G10: 101.6 | H10: =D10/G10 -> 23.913594
A11: Red / RGB | B11: MO | C11: =C8*0.204137629 -> 4115.1635 | D11: =D8*0.204137629 -> 519.11988 | E11: =E8*0.204137629 -> 256.71918 | F11: =D11/'No Lens'!D11 -> 0.88285694 | G11: 29.1 | H11: =D11/G11 -> 17.839171
A12: Green / RGB | B12: MO | C12: =C8*0.355680917 -> 7170.0898 | D12: =D8*0.355680917 -> 904.4929 | E12: =E8*0.355680917 -> 447.29683 | F12: =D12/'No Lens'!D12 -> 0.89820546 | G12: 34.3 | H12: =D12/G12 -> 26.370055
A13: Blue / RGB | B13: MO | C13: =C8*0.041302273 -> 832.60302 | D13: =D8*0.041302273 -> 105.03125 | E13: =E8*0.041302273 -> 51.940869 | F13: =D13/'No Lens'!D13 -> 0.88261558 | G13: 32.2 | H13: =D13/G13 -> 3.2618402
A14: Full ON / Direct | B14: MO | C14: =C8*1.043529672 -> 21036.275 | D14: =D8*1.043529672 -> 2653.6852 | E14: =E8*1.043529672 -> 1312.3209 | F14: =D14/'No Lens'!D14 -> 0.89109643 | G14: 108 | H14: =D14/G14 -> 24.571159
A15: Red / Direct | B15: MO | C15: =C8*0.203860398 -> 4109.5749 | D15: =D8*0.203860398 -> 518.41489 | E15: =E8*0.203860398 -> 256.37054 | F15: =D15/'No Lens'!D15 -> 0.88466704 | G15: 28.8 | H15: =D15/G15 -> 18.000517
A16: Lime / Direct | B16: MO | C16: =C8*0.454361902 -> 9159.3771 | D16: =D8*0.454361902 -> 1155.4376 | E16: =E8*0.454361902 -> 571.39596 | F16: =D16/'No Lens'!D16 -> 0.89154137 | G16: 22.2 | H16: =D16/G16 -> 52.04674
A17: Green / Direct | B17: MO | C17: =C8*0.357567841 -> 7208.1279 | D17: =D8*0.357567841 -> 909.29132 | E17: =E8*0.357567841 -> 449.66979 | F17: =D17/'No Lens'!D17 -> 0.90028844 | G17: 34.2 | H17: =D17/G17 -> 26.587466
A18: Blue / Direct | B18: MO | C18: =C8*0.037144801 -> 748.7935 | D18: =D8*0.037144801 -> 94.458845 | E18: =E8*0.037144801 -> 46.71252 | F18: =D18/'No Lens'!D18 -> 0.88279294 | G18: 32.3 | H18: =D18/G18 -> 2.9244224
B20: For Field diameter at any distance, multiply distance by | F20: =2*TAN(C5*3.1415926535/360) -> 1.1687056
B22: For Beam diameter at any distance, multiply distance by | F22: =2*TAN(B5*3.1415926535/360) -> 0.53964142
G23: Dist for 1.0 fc
B24: Throw Distance (ft) | C24: 10 | D24: 15 | E24: 20 | F24: 25 | G24: =SQRT(C8) -> 141.98158
B25: Throw Distance (m) | C25: =C24*0.3048 -> 3.048 | D25: =D24*0.3048 -> 4.572 | E25: =E24*0.3048 -> 6.096 | F25: =F24*0.3048 -> 7.62 | G25: =G24*0.3048 -> 43.275987
B26: Field Diameter (ft) | C26: =C24*F20 -> 11.687056 | D26: =D24*F20 -> 17.530585 | E26: =E24*F20 -> 23.374113 | F26: =F24*F20 -> 29.217641
B27: Field Diameter (m) | C27: =C25*F20 -> 3.5622148 | D27: =D25*F20 -> 5.3433222 | E27: =E25*F20 -> 7.1244296 | F27: =F25*F20 -> 8.905537
B28: Illuminance (fc) | C28: =C8/(C24*C24) -> 201.5877 | D28: =C8/(D24*D24) -> 89.594533 | E28: =C8/(E24*E24) -> 50.396925 | F28: =C8/(F24*F24) -> 32.254032
B29: Illuminance (lux) | C29: =C28*10.7639 -> 2169.8698 | D29: =D28*10.7639 -> 964.3866 | E29: =E28*10.7639 -> 542.46746 | F29: =F28*10.7639 -> 347.17918
B31: Beam Angle | C31: Field Angle
A32: Vertical | B32: 16 | C32: 32.1
B34: For Field height at any distance, multiply distance by | F34: =2*TAN(C32*3.1415926535/360) -> 0.57538008
B36: For Beam height at any distance, multiply distance by | F36: =2*TAN(B32*3.1415926535/360) -> 0.28108167
A38: Test Distance | B38: Iso-Illuminance Diagram grid lines
A39: 67.75 | B39: 10 | C39: 20 | D39: 30 | E39: 40 | F39: 50
B40: =B39/A39 -> 0.14760148 | C40: =C39/A39 -> 0.29520295 | D40: =D39/A39 -> 0.44280443 | E40: =E39/A39 -> 0.5904059 | F40: =F39/A39 -> 0.73800738
A46: Measurement: MO rgb mode - Intensity
A48: Degrees | B48: (Cd)
A49: -40.96029 | B49: 0
A50: -40.90152 | B50: 0
A51: -40.84275 | B51: 0
A52: -40.78399 | B52: 0
A53: -40.72522 | B53: 0
A54: -40.66645 | B54: 0
...

Sheet ML
A2: Color Source PAR Deep Blue | B2: 43656
B4: Beam Angle | C4: Field Angle
A5: Horizontal | B5: 42.7 | C5: 59.4
F6: Lens Efficiency | G6: Power Consump (Watts) | H6: Efficacy (lm/W)
A7: Mode | B7: Accessory Lens | C7: Candela | D7: Field Lumens | E7: Beam Lumens
A8: Full ON / RGB | B8: ML | C8: ='No Lens'!C8*ML!K8 -> 17933.522 | D8: ='No Lens'!D8*ML!L8 -> 2834.9577 | E8: ='No Lens'!E8*ML!M8 -> 1718.7368 | F8: =D8/'No Lens'!D8 -> 1.0216064 | G8: 101.2 | H8: =D8/G8 -> 28.013416 | K8: 0.35099764 | L8: 1.0216064 | M8: 0.98664572
A9: 3200K / RGB | B9: ML | C9: =C8*0.96990745 -> 17393.857 | D9: =D8*0.96990745 -> 2749.6466 | E9: =E8*0.96990745 -> 1667.0157 | F9: =D9/'No Lens'!D9 -> 0.99193601 | G9: 72.3 | H9: =D9/G9 -> 38.031074
A10: 5600K / RGB | B10: ML | C10: =C8*0.955419195 -> 17134.032 | D10: =D8*0.955419195 -> 2708.573 | E10: =E8*0.955419195 -> 1642.1142 | F10: =D10/'No Lens'!D10 -> 0.99470181 | G10: 101.6 | H10: =D10/G10 -> 26.659183
A11: Red / RGB | B11: ML | C11: =C8*0.204137629 -> 3660.9067 | D11: =D8*0.204137629 -> 578.72155 | E11: =E8*0.204137629 -> 350.85886 | F11: =D11/'No Lens'!D11 -> 0.98422032 | G11: 29.1 | H11: =D11/G11 -> 19.887338
A12: Green / RGB | B12: ML | C12: =C8*0.355680917 -> 6378.6117 | D12: =D8*0.355680917 -> 1008.3404 | E12: =E8*0.355680917 -> 611.3219 | F12: =D12/'No Lens'!D12 -> 1.001331 | G12: 34.3 | H12: =D12/G12 -> 29.397678
A13: Blue / RGB | B13: ML | C13: =C8*0.041302273 -> 740.69524 | D13: =D8*0.041302273 -> 117.0902 | E13: =E8*0.041302273 -> 70.987738 | F13: =D13/'No Lens'!D13 -> 0.98395124 | G13: 32.2 | H13: =D13/G13 -> 3.6363416
A14: Full ON / Direct | B14: ML | C14: =C8*1.043529672 -> 18714.163 | D14: =D8*1.043529672 -> 2958.3625 | E14: =E8*1.043529672 -> 1793.5529 | F14: =D14/'No Lens'!D14 -> 0.99340581 | G14: 108 | H14: =D14/G14 -> 27.392245
A15: Red / Direct | B15: ML | C15: =C8*0.203860398 -> 3655.935 | D15: =D8*0.203860398 -> 577.93561 | E15: =E8*0.203860398 -> 350.38238 | F15: =D15/'No Lens'!D15 -> 0.98623824 | G15: 28.8 | H15: =D15/G15 -> 20.067209
A16: Lime / Direct | B16: ML | C16: =C8*0.454361902 -> 8148.3094 | D16: =D8*0.454361902 -> 1288.0968 | E16: =E8*0.454361902 -> 780.92854 | F16: =D16/'No Lens'!D16 -> 0.99390184 | G16: 22.2 | H16: =D16/G16 -> 58.022378
A17: Green / Direct | B17: ML | C17: =C8*0.357567841 -> 6412.4509 | D17: =D8*0.357567841 -> 1013.6897 | E17: =E8*0.357567841 -> 614.56502 | F17: =D17/'No Lens'!D17 -> 1.0036532 | G17: 34.2 | H17: =D17/G17 -> 29.64005
A18: Blue / Direct | B18: ML | C18: =C8*0.037144801 -> 666.13712 | D18: =D8*0.037144801 -> 105.30394 | E18: =E8*0.037144801 -> 63.842138 | F18: =D18/'No Lens'!D18 -> 0.98414898 | G18: 32.3 | H18: =D18/G18 -> 3.2601839
B20: For Field diameter at any distance, multiply distance by | F20: =2*TAN(C5*3.1415926535/360) -> 1.1407799
B22: For Beam diameter at any distance, multiply distance by | F22: =2*TAN(B5*3.1415926535/360) -> 0.78177874
G23: Dist for 1.0 fc
B24: Throw Distance (ft) | C24: 10 | D24: 15 | E24: 20 | F24: 25 | G24: =SQRT(C8) -> 133.9161
B25: Throw Distance (m) | C25: =C24*0.3048 -> 3.048 | D25: =D24*0.3048 -> 4.572 | E25: =E24*0.3048 -> 6.096 | F25: =F24*0.3048 -> 7.62 | G25: =G24*0.3048 -> 40.817628
B26: Field Diameter (ft) | C26: =C24*F20 -> 11.407799 | D26: =D24*F20 -> 17.111698 | E26: =E24*F20 -> 22.815597 | F26: =F24*F20 -> 28.519496
B27: Field Diameter (m) | C27: =C25*F20 -> 3.477097 | D27: =D25*F20 -> 5.2156455 | E27: =E25*F20 -> 6.954194 | F27: =F25*F20 -> 8.6927425
B28: Illuminance (fc) | C28: =C8/(C24*C24) -> 179.33522 | D28: =C8/(D24*D24) -> 79.704544 | E28: =C8/(E24*E24) -> 44.833806 | F28: =C8/(F24*F24) -> 28.693636
B29: Illuminance (lux) | C29: =C28*10.7639 -> 1930.3464 | D29: =D28*10.7639 -> 857.93174 | E29: =E28*10.7639 -> 482.5866 | F29: =F28*10.7639 -> 308.85543
B31: Beam Angle | C31: Field Angle
A32: Vertical | B32: 15.2 | C32: 30.6
B34: For Field height at any distance, multiply distance by | F34: =2*TAN(C32*3.1415926535/360) -> 0.54713809
B36: For Beam height at any distance, multiply distance by | F36: =2*TAN(B32*3.1415926535/360) -> 0.26685697
A38: Test Distance | B38: Iso-Illuminance Diagram grid lines
A39: 67.65 | B39: 10 | C39: 20 | D39: 30 | E39: 40 | F39: 50
B40: =B39/A39 -> 0.14781966 | C40: =C39/A39 -> 0.29563932 | D40: =D39/A39 -> 0.44345898 | E40: =E39/A39 -> 0.59127864 | F40: =F39/A39 -> 0.7390983
A46: Measurement: ML rgb mode - Intensity
A48: Degrees | B48: (Cd)
A49: -40.96029 | B49: 0
A50: -40.90152 | B50: 0
A51: -40.84275 | B51: 0
A52: -40.78399 | B52: 0
A53: -40.72522 | B53: 0
A54: -40.66645 | B54: 0
...

Sheet WR
A2: Color Source PAR Deep Blue | B2: 43656
B4: Beam Angle | C4: Field Angle
B5: 45.4 | C5: 77.3
F6: Lens Efficiency | G6: Power Consump (Watts) | H6: Efficacy (lm/W)
A7: Mode | B7: Accessory Lens | C7: Candela | D7: Field Lumens | E7: Beam Lumens
A8: Full ON / RGB | B8: WR | C8: ='No Lens'!C8*WR!K8 -> 6390.7357 | D8: ='No Lens'!D8*WR!L8 -> 2837.5646 | E8: ='No Lens'!E8*WR!M8 -> 1461.4737 | F8: =D8/'No Lens'!D8 -> 1.0225458 | G8: 101.2 | H8: =D8/G8 -> 28.039176 | K8: 0.12508045 | L8: 1.0225458 | M8: 0.83896308
A9: 3200K / RGB | B9: WR | C9: =C8*0.96990745 -> 6198.4221 | D9: =D8*0.96990745 -> 2752.175 | E9: =E8*0.96990745 -> 1417.4942 | F9: =D9/'No Lens'!D9 -> 0.99284813 | G9: 72.3 | H9: =D9/G9 -> 38.066045
A10: 5600K / RGB | B10: WR | C10: =C8*0.955419195 -> 6105.8315 | D10: =D8*0.955419195 -> 2711.0637 | E10: =E8*0.955419195 -> 1396.32 | F10: =D10/'No Lens'!D10 -> 0.99561648 | G10: 101.6 | H10: =D10/G10 -> 26.683698
A11: Red / RGB | B11: WR | C11: =C8*0.204137629 -> 1304.5896 | D11: =D8*0.204137629 -> 579.25371 | E11: =E8*0.204137629 -> 298.34177 | F11: =D11/'No Lens'!D11 -> 0.98512535 | G11: 29.1 | H11: =D11/G11 -> 19.905626
A12: Green / RGB | B12: WR | C12: =C8*0.355680917 -> 2273.0627 | D12: =D8*0.355680917 -> 1009.2676 | E12: =E8*0.355680917 -> 519.8183 | F12: =D12/'No Lens'!D12 -> 1.0022518 | G12: 34.3 | H12: =D12/G12 -> 29.424711
A13: Blue / RGB | B13: WR | C13: =C8*0.041302273 -> 263.95191 | D13: =D8*0.041302273 -> 117.19787 | E13: =E8*0.041302273 -> 60.362185 | F13: =D13/'No Lens'!D13 -> 0.98485603 | G13: 32.2 | H13: =D13/G13 -> 3.6396853
A14: Full ON / Direct | B14: WR | C14: =C8*1.043529672 -> 6668.9223 | D14: =D8*1.043529672 -> 2961.0828 | E14: =E8*1.043529672 -> 1525.0912 | F14: =D14/'No Lens'!D14 -> 0.99431929 | G14: 108 | H14: =D14/G14 -> 27.417434
A15: Red / Direct | B15: WR | C15: =C8*0.203860398 -> 1302.8179 | D15: =D8*0.203860398 -> 578.46705 | E15: =E8*0.203860398 -> 297.93661 | F15: =D15/'No Lens'!D15 -> 0.98714513 | G15: 28.8 | H15: =D15/G15 -> 20.085661
A16: Lime / Direct | B16: WR | C16: =C8*0.454361902 -> 2903.7068 | D16: =D8*0.454361902 -> 1289.2812 | E16: =E8*0.454361902 -> 664.03796 | F16: =D16/'No Lens'!D16 -> 0.99481577 | G16: 22.2 | H16: =D16/G16 -> 58.075732
A17: Green / Direct | B17: WR | C17: =C8*0.357567841 -> 2285.1216 | D17: =D8*0.357567841 -> 1014.6218 | E17: =E8*0.357567841 -> 522.57599 | F17: =D17/'No Lens'!D17 -> 1.0045761 | G17: 34.2 | H17: =D17/G17 -> 29.667305
A18: Blue / Direct | B18: WR | C18: =C8*0.037144801 -> 237.38261 | D18: =D8*0.037144801 -> 105.40077 | E18: =E8*0.037144801 -> 54.286149 | F18: =D18/'No Lens'!D18 -> 0.98505394 | G18: 32.3 | H18: =D18/G18 -> 3.2631818
B20: For Field diameter at any distance, multiply distance by | F20: =2*TAN(C5*3.1415926535/360) -> 1.5994386
B22: For Beam diameter at any distance, multiply distance by | F22: =2*TAN(B5*3.1415926535/360) -> 0.83661812
G23: Dist for 1.0 fc
B24: Throw Distance (ft) | C24: 10 | D24: 15 | E24: 20 | F24: 25 | G24: =SQRT(C8) -> 79.942077
B25: Throw Distance (m) | C25: =C24*0.3048 -> 3.048 | D25: =D24*0.3048 -> 4.572 | E25: =E24*0.3048 -> 6.096 | F25: =F24*0.3048 -> 7.62 | G25: =G24*0.3048 -> 24.366345
B26: Field Diameter (ft) | C26: =C24*F20 -> 15.994386 | D26: =D24*F20 -> 23.991579 | E26: =E24*F20 -> 31.988772 | F26: =F24*F20 -> 39.985965
B27: Field Diameter (m) | C27: =C25*F20 -> 4.8750888 | D27: =D25*F20 -> 7.3126332 | E27: =E25*F20 -> 9.7501776 | F27: =F25*F20 -> 12.187722
B28: Illuminance (fc) | C28: =C8/(C24*C24) -> 63.907357 | D28: =C8/(D24*D24) -> 28.40327 | E28: =C8/(E24*E24) -> 15.976839 | F28: =C8/(F24*F24) -> 10.225177
B29: Illuminance (lux) | C29: =C28*10.7639 -> 687.8924 | D29: =D28*10.7639 -> 305.72995 | E29: =E28*10.7639 -> 171.9731 | F29: =F28*10.7639 -> 110.06278
A31: Test Distance | B31: Iso-Illuminance Diagram grid lines
A32: 55.75 | B32: 10 | C32: 20 | D32: 30 | E32: 40
B33: =B32/A32 -> 0.1793722 | C33: =C32/A32 -> 0.35874439 | D33: =D32/A32 -> 0.53811659 | E33: =E32/A32 -> 0.71748879
A60: Measurement: WR rgb mode re-shoot - Intensity
A62: Degrees | B62: (Cd)
A63: -46.53442 | B63: 0
A64: -46.45431 | B64: 0
A65: -46.37419 | B65: 0
A66: -46.29408 | B66: 0
A67: -46.21396 | B67: 0
A68: -46.13384 | B68: 0
A69: -46.05372 | B69: 0
A70: -45.97361 | B70: 0
A71: -45.89349 | B71: 0
A72: -45.81337 | B72: 0
...

Sheet WO
A2: Color Source PAR Deep Blue | B2: 43656
B4: Beam Angle | C4: Field Angle
A5: Horizontal | B5: 30.1 | C5: 59.9
F6: Lens Efficiency | G6: Power Consump (Watts) | H6: Efficacy (lm/W)
A7: Mode | B7: Accessory Lens | C7: Candela | D7: Field Lumens | E7: Beam Lumens
A8: Full ON / RGB | B8: WO | C8: ='No Lens'!C8*WO!K8 -> 20035.058 | D8: ='No Lens'!D8*WO!L8 -> 2510.4039 | E8: ='No Lens'!E8*WO!M8 -> 1235.6842 | F8: =D8/'No Lens'!D8 -> 0.90465007 | G8: 101.2 | H8: =D8/G8 -> 24.806363 | K8: 0.39212922 | L8: 0.90465007 | M8: 0.709348
A9: 3200K / RGB | B9: WO | C9: =C8*0.96990745 -> 19432.152 | D9: =D8*0.96990745 -> 2434.8595 | E9: =E8*0.96990745 -> 1198.4993 | F9: =D9/'No Lens'!D9 -> 0.87837644 | G9: 72.3 | H9: =D9/G9 -> 33.677171
A10: 5600K / RGB | B10: WO | C10: =C8*0.955419195 -> 19141.879 | D10: =D8*0.955419195 -> 2398.4881 | E10: =E8*0.955419195 -> 1180.5964 | F10: =D10/'No Lens'!D10 -> 0.8808256 | G10: 101.6 | H10: =D10/G10 -> 23.607167
A11: Red / RGB | B11: WO | C11: =C8*0.204137629 -> 4089.9093 | D11: =D8*0.204137629 -> 512.46791 | E11: =E8*0.204137629 -> 252.24964 | F11: =D11/'No Lens'!D11 -> 0.87154406 | G11: 29.1 | H11: =D11/G11 -> 17.610581
A12: Green / RGB | B12: WO | C12: =C8*0.355680917 -> 7126.0879 | D12: =D8*0.355680917 -> 892.90278 | E12: =E8*0.355680917 -> 439.50929 | F12: =D12/'No Lens'!D12 -> 0.88669591 | G12: 34.3 | H12: =D12/G12 -> 26.032151
A13: Blue / RGB | B13: WO | C13: =C8*0.041302273 -> 827.49344 | D13: =D8*0.041302273 -> 103.68539 | E13: =E8*0.041302273 -> 51.036567 | F13: =D13/'No Lens'!D13 -> 0.87130579 | G13: 32.2 | H13: =D13/G13 -> 3.2200431
A14: Full ON / Direct | B14: WO | C14: =C8*1.043529672 -> 20907.178 | D14: =D8*1.043529672 -> 2619.681 | E14: =E8*1.043529672 -> 1289.4731 | F14: =D14/'No Lens'!D14 -> 0.87967797 | G14: 108 | H14: =D14/G14 -> 24.256306
A15: Red / Direct | B15: WO | C15: =C8*0.203860398 -> 4084.3549 | D15: =D8*0.203860398 -> 511.77195 | E15: =E8*0.203860398 -> 251.90707 | F15: =D15/'No Lens'!D15 -> 0.87333097 | G15: 28.8 | H15: =D15/G15 -> 17.769859
A16: Lime / Direct | B16: WO | C16: =C8*0.454361902 -> 9103.1671 | D16: =D8*0.454361902 -> 1140.6319 | E16: =E8*0.454361902 -> 561.44783 | F16: =D16/'No Lens'!D16 -> 0.88011722 | G16: 22.2 | H16: =D16/G16 -> 51.379816
A17: Green / Direct | B17: WO | C17: =C8*0.357567841 -> 7163.8925 | D17: =D8*0.357567841 -> 897.63972 | E17: =E8*0.357567841 -> 441.84094 | F17: =D17/'No Lens'!D17 -> 0.8887522 | G17: 34.2 | H17: =D17/G17 -> 26.246775
A18: Blue / Direct | B18: WO | C18: =C8*0.037144801 -> 744.19825 | D18: =D8*0.037144801 -> 93.248455 | E18: =E8*0.037144801 -> 45.899244 | F18: =D18/'No Lens'!D18 -> 0.87148089 | G18: 32.3 | H18: =D18/G18 -> 2.8869491
B20: For Field diameter at any distance, multiply distance by | F20: =2*TAN(C5*3.1415926535/360) -> 1.1523746
B22: For Beam diameter at any distance, multiply distance by | F22: =2*TAN(B5*3.1415926535/360) -> 0.53776946
G23: Dist for 1.0 fc
B24: Throw Distance (ft) | C24: 10 | D24: 15 | E24: 20 | F24: 25 | G24: =SQRT(C8) -> 141.54525
B25: Throw Distance (m) | C25: =C24*0.3048 -> 3.048 | D25: =D24*0.3048 -> 4.572 | E25: =E24*0.3048 -> 6.096 | F25: =F24*0.3048 -> 7.62 | G25: =G24*0.3048 -> 43.142993
B26: Field Diameter (ft) | C26: =C24*F20 -> 11.523746 | D26: =D24*F20 -> 17.285619 | E26: =E24*F20 -> 23.047492 | F26: =F24*F20 -> 28.809365
B27: Field Diameter (m) | C27: =C25*F20 -> 3.5124378 | D27: =D25*F20 -> 5.2686567 | E27: =E25*F20 -> 7.0248756 | F27: =F25*F20 -> 8.7810945
B28: Illuminance (fc) | C28: =C8/(C24*C24) -> 200.35058 | D28: =C8/(D24*D24) -> 89.044703 | E28: =C8/(E24*E24) -> 50.087645 | F28: =C8/(F24*F24) -> 32.056093
B29: Illuminance (lux) | C29: =C28*10.7639 -> 2156.5536 | D29: =D28*10.7639 -> 958.46828 | E29: =E28*10.7639 -> 539.13841 | F29: =F28*10.7639 -> 345.04858
B31: Beam Angle | C31: Field Angle
A32: Vertical | B32: 15.9 | C32: 32.1
B34: For Field height at any distance, multiply distance by | F34: =2*TAN(C32*3.1415926535/360) -> 0.57538008
B36: For Beam height at any distance, multiply distance by | F36: =2*TAN(B32*3.1415926535/360) -> 0.27930208
A38: Test Distance | B38: Iso-Illuminance Diagram grid lines
A39: 75.5 | B39: 10 | C39: 20 | D39: 30 | E39: 40 | F39: 50
B40: =B39/A39 -> 0.13245033 | C40: =C39/A39 -> 0.26490066 | D40: =D39/A39 -> 0.39735099 | E40: =E39/A39 -> 0.52980132 | F40: =F39/A39 -> 0.66225166
A46: Measurement: WO rgb mode - Intensity
A48: Degrees | B48: (Cd)
A49: -37.91538 | B49: 0
A50: -37.86098 | B50: 0
A51: -37.80658 | B51: 0
A52: -37.75219 | B52: 0
A53: -37.69779 | B53: 0
A54: -37.64339 | B54: 0
...

Sheet WL
A2: Color Source PAR Deep Blue | B2: 43656
B4: Beam Angle | C4: Field Angle
A5: Horizontal | B5: 66.1 | C5: 89.4
F6: Lens Efficiency | G6: Power Consump (Watts) | H6: Efficacy (lm/W)
A7: Mode | B7: Accessory Lens | C7: Candela | D7: Field Lumens | E7: Beam Lumens
A8: Full ON / RGB | B8: WL* | C8: ='No Lens'!C8*WL!K8 -> 13263.791 | D8: ='No Lens'!D8*WL!L8 -> 2992.6726 | E8: ='No Lens'!E8*WL!M8 -> 1506.6316 | F8: =D8/'No Lens'!D8 -> 1.0784406 | G8: 101.2 | H8: =D8/G8 -> 29.571864 | K8: 0.25960094 | L8: 1.0784406 | M8: 0.8648861
A9: 3200K / RGB | B9: WL* | C9: =C8*0.96990745 -> 12864.65 | D9: =D8*0.96990745 -> 2902.6155 | E9: =E8*0.96990745 -> 1461.2932 | F9: =D9/'No Lens'!D9 -> 1.0471196 | G9: 72.3 | H9: =D9/G9 -> 40.146825
A10: 5600K / RGB | B10: WL* | C10: =C8*0.955419195 -> 12672.481 | D10: =D8*0.955419195 -> 2859.2569 | E10: =E8*0.955419195 -> 1439.4647 | F10: =D10/'No Lens'!D10 -> 1.0500392 | G10: 101.6 | H10: =D10/G10 -> 28.142292
A11: Red / RGB | B11: WL* | C11: =C8*0.204137629 -> 2707.6389 | D11: =D8*0.204137629 -> 610.91709 | E11: =E8*0.204137629 -> 307.5602 | F11: =D11/'No Lens'!D11 -> 1.0389746 | G11: 29.1 | H11: =D11/G11 -> 20.993715
A12: Green / RGB | B12: WL* | C12: =C8*0.355680917 -> 4717.6774 | D12: =D8*0.355680917 -> 1064.4365 | E12: =E8*0.355680917 -> 535.8801 | F12: =D12/'No Lens'!D12 -> 1.0570373 | G12: 34.3 | H12: =D12/G12 -> 31.033135
A13: Blue / RGB | B13: WL* | C13: =C8*0.041302273 -> 547.82472 | D13: =D8*0.041302273 -> 123.60418 | E13: =E8*0.041302273 -> 62.227309 | F13: =D13/'No Lens'!D13 -> 1.0386906 | G13: 32.2 | H13: =D13/G13 -> 3.8386392
A14: Full ON / Direct | B14: WL* | C14: =C8*1.043529672 -> 13841.16 | D14: =D8*1.043529672 -> 3122.9427 | E14: =E8*1.043529672 -> 1572.2148 | F14: =D14/'No Lens'!D14 -> 1.0486711 | G14: 108 | H14: =D14/G14 -> 28.916136
A15: Red / Direct | B15: WL* | C15: =C8*0.203860398 -> 2703.9617 | D15: =D8*0.203860398 -> 610.08743 | E15: =E8*0.203860398 -> 307.14251 | F15: =D15/'No Lens'!D15 -> 1.0411048 | G15: 28.8 | H15: =D15/G15 -> 21.183591
A16: Lime / Direct | B16: WL* | C16: =C8*0.454361902 -> 6026.5613 | D16: =D8*0.454361902 -> 1359.7564 | E16: =E8*0.454361902 -> 684.55599 | F16: =D16/'No Lens'!D16 -> 1.0491948 | G16: 22.2 | H16: =D16/G16 -> 61.250289
A17: Green / Direct | B17: WL* | C17: =C8*0.357567841 -> 4742.7051 | D17: =D8*0.357567841 -> 1070.0835 | E17: =E8*0.357567841 -> 538.723 | F17: =D17/'No Lens'!D17 -> 1.0594886 | G17: 34.2 | H17: =D17/G17 -> 31.288991
A18: Blue / Direct | B18: WL* | C18: =C8*0.037144801 -> 492.68088 | D18: =D8*0.037144801 -> 111.16223 | E18: =E8*0.037144801 -> 55.96353 | F18: =D18/'No Lens'!D18 -> 1.0388993 | G18: 32.3 | H18: =D18/G18 -> 3.4415551
B20: For Field diameter at any distance, multiply distance by | F20: =2*TAN(C5*3.1415926535/360) -> 1.979165
B22: For Beam diameter at any distance, multiply distance by | F22: =2*TAN(B5*3.1415926535/360) -> 1.301298
G23: Dist for 1.0 fc
B24: Throw Distance (ft) | C24: 10 | D24: 15 | E24: 20 | F24: 25 | G24: =SQRT(C8) -> 115.16853
B25: Throw Distance (m) | C25: =C24*0.3048 -> 3.048 | D25: =D24*0.3048 -> 4.572 | E25: =E24*0.3048 -> 6.096 | F25: =F24*0.3048 -> 7.62 | G25: =G24*0.3048 -> 35.103369
B26: Field Diameter (ft) | C26: =C24*F20 -> 19.79165 | D26: =D24*F20 -> 29.687474 | E26: =E24*F20 -> 39.583299 | F26: =F24*F20 -> 49.479124
B27: Field Diameter (m) | C27: =C25*F20 -> 6.0324948 | D27: =D25*F20 -> 9.0487422 | E27: =E25*F20 -> 12.06499 | F27: =F25*F20 -> 15.081237
B28: Illuminance (fc) | C28: =C8/(C24*C24) -> 132.63791 | D28: =C8/(D24*D24) -> 58.950182 | E28: =C8/(E24*E24) -> 33.159478 | F28: =C8/(F24*F24) -> 21.222066
B29: Illuminance (lux) | C29: =C28*10.7639 -> 1427.7012 | D29: =D28*10.7639 -> 634.53387 | E29: =E28*10.7639 -> 356.9253 | F29: =F28*10.7639 -> 228.43219
B31: Beam Angle | C31: Field Angle
A32: Vertical | B32: 15.3 | C32: 30.6
B34: For Field height at any distance, multiply distance by | F34: =2*TAN(C32*3.1415926535/360) -> 0.54713809
B36: For Beam height at any distance, multiply distance by | F36: =2*TAN(B32*3.1415926535/360) -> 0.26863358
A38: Test Distance | B38: Iso-Illuminance Diagram grid lines
A39: 47.375 | B39: 8 | C39: 16 | D39: 24 | E39: 32 | F39: 40
B40: =B39/A39 -> 0.16886544 | C40: =C39/A39 -> 0.33773087 | D40: =D39/A39 -> 0.50659631 | E40: =E39/A39 -> 0.67546174 | F40: =F39/A39 -> 0.84432718
A46: Measurement: WL* - Intensity
A48: Degrees | B48: (Cd)
A49: -51.15731 | B49: 0
A50: -51.08391 | B50: 0
A51: -51.01051 | B51: 0
A52: -50.93712 | B52: 0
A53: -50.86372 | B53: 0
A54: -50.79033 | B54: 0
...

Sheet XWR
A2: Color Source PAR Deep Blue | B2: 43656
B4: Beam Angle | C4: Field Angle
B5: 70.6 | C5: 95.4
F6: Lens Efficiency | G6: Power Consump (Watts) | H6: Efficacy (lm/W)
A7: Mode | B7: Accessory Lens | C7: Candela | D7: Field Lumens | E7: Beam Lumens
A8: Full ON / RGB | B8: XWR | C8: ='No Lens'!C8*XWR!K8 -> 3379.3697 | D8: ='No Lens'!D8*XWR!L8 -> 2986.1555 | E8: ='No Lens'!E8*XWR!M8 -> 1696.8421 | F8: =D8/'No Lens'!D8 -> 1.0760921 | G8: 101.2 | H8: =D8/G8 -> 29.507465 | K8: 0.066141539 | L8: 1.0760921 | M8: 0.97407698
A9: 3200K / RGB | B9: XWR | C9: =C8*0.96990745 -> 3277.6758 | D9: =D8*0.96990745 -> 2896.2944 | E9: =E8*0.96990745 -> 1645.7798 | F9: =D9/'No Lens'!D9 -> 1.0448393 | G9: 72.3 | H9: =D9/G9 -> 40.059397
A10: 5600K / RGB | B10: XWR | C10: =C8*0.955419195 -> 3228.7146 | D10: =D8*0.955419195 -> 2853.0303 | E10: =E8*0.955419195 -> 1621.1955 | F10: =D10/'No Lens'!D10 -> 1.0477526 | G10: 101.6 | H10: =D10/G10 -> 28.081006
A11: Red / RGB | B11: XWR | C11: =C8*0.204137629 -> 689.85651 | D11: =D8*0.204137629 -> 609.5867 | E11: =E8*0.204137629 -> 346.38932 | F11: =D11/'No Lens'!D11 -> 1.0367121 | G11: 29.1 | H11: =D11/G11 -> 20.947996
A12: Green / RGB | B12: XWR | C12: =C8*0.355680917 -> 1201.9773 | D12: =D8*0.355680917 -> 1062.1185 | E12: =E8*0.355680917 -> 603.53436 | F12: =D12/'No Lens'!D12 -> 1.0547354 | G12: 34.3 | H12: =D12/G12 -> 30.965554
A13: Blue / RGB | B13: XWR | C13: =C8*0.041302273 -> 139.57565 | D13: =D8*0.041302273 -> 123.33501 | E13: =E8*0.041302273 -> 70.083436 | F13: =D13/'No Lens'!D13 -> 1.0364286 | G13: 32.2 | H13: =D13/G13 -> 3.8302798
A14: Full ON / Direct | B14: XWR | C14: =C8*1.043529672 -> 3526.4725 | D14: =D8*1.043529672 -> 3116.1418 | E14: =E8*1.043529672 -> 1770.7051 | F14: =D14/'No Lens'!D14 -> 1.0463875 | G14: 108 | H14: =D14/G14 -> 28.853165
A15: Red / Direct | B15: XWR | C15: =C8*0.203860398 -> 688.91964 | D15: =D8*0.203860398 -> 608.75884 | E15: =E8*0.203860398 -> 345.91891 | F15: =D15/'No Lens'!D15 -> 1.0388376 | G15: 28.8 | H15: =D15/G15 -> 21.13746
A16: Lime / Direct | B16: XWR | C16: =C8*0.454361902 -> 1535.4568 | D16: =D8*0.454361902 -> 1356.7953 | E16: =E8*0.454361902 -> 770.98041 | F16: =D16/'No Lens'!D16 -> 1.0469099 | G16: 22.2 | H16: =D16/G16 -> 61.116905
A17: Green / Direct | B17: XWR | C17: =C8*0.357567841 -> 1208.3539 | D17: =D8*0.357567841 -> 1067.7532 | E17: =E8*0.357567841 -> 606.73617 | F17: =D17/'No Lens'!D17 -> 1.0571814 | G17: 34.2 | H17: =D17/G17 -> 31.220853
A18: Blue / Direct | B18: XWR | C18: =C8*0.037144801 -> 125.52601 | D18: =D8*0.037144801 -> 110.92015 | E18: =E8*0.037144801 -> 63.028862 | F18: =D18/'No Lens'!D18 -> 1.0366369 | G18: 32.3 | H18: =D18/G18 -> 3.4340604
B20: For Field diameter at any distance, multiply distance by | F20: =2*TAN(C5*3.1415926535/360) -> 2.1979713
B22: For Beam diameter at any distance, multiply distance by | F22: =2*TAN(B5*3.1415926535/360) -> 1.4160789
G23: Dist for 1.0 fc
B24: Throw Distance (ft) | C24: 10 | D24: 15 | E24: 20 | F24: 25 | G24: =SQRT(C8) -> 58.132346
B25: Throw Distance (m) | C25: =C24*0.3048 -> 3.048 | D25: =D24*0.3048 -> 4.572 | E25: =E24*0.3048 -> 6.096 | F25: =F24*0.3048 -> 7.62 | G25: =G24*0.3048 -> 17.718739
B26: Field Diameter (ft) | C26: =C24*F20 -> 21.979713 | D26: =D24*F20 -> 32.96957 | E26: =E24*F20 -> 43.959426 | F26: =F24*F20 -> 54.949283
B27: Field Diameter (m) | C27: =C25*F20 -> 6.6994165 | D27: =D25*F20 -> 10.049125 | E27: =E25*F20 -> 13.398833 | F27: =F25*F20 -> 16.748541
B28: Illuminance (fc) | C28: =C8/(C24*C24) -> 33.793697 | D28: =C8/(D24*D24) -> 15.019421 | E28: =C8/(E24*E24) -> 8.4484242 | F28: =C8/(F24*F24) -> 5.4069915
B29: Illuminance (lux) | C29: =C28*10.7639 -> 363.75197 | D29: =D28*10.7639 -> 161.66754 | E29: =E28*10.7639 -> 90.937993 | F29: =F28*10.7639 -> 58.200315
A31: Test Distance | B31: Iso-Illuminance Diagram grid lines
A32: 43.25 | B32: 10 | C32: 20 | D32: 30 | E32: 40
B33: =B32/A32 -> 0.23121387 | C33: =C32/A32 -> 0.46242775 | D33: =D32/A32 -> 0.69364162 | E33: =E32/A32 -> 0.92485549
A60: Measurement: WR rgb mode - Intensity
A62: Measurement: XWR rgb mode re-shoot - Intensity
A64: Degrees | B64: (Cd)
A65: -53.66054 | B65: 0
A66: -53.58355 | B66: 0
A67: -53.50657 | B67: 0
A68: -53.42958 | B68: 0
A69: -53.35259 | B69: 0
A70: -53.2756 | B70: 0
A71: -53.19862 | B71: 0
A72: -53.12163 | B72: 0
A73: -53.04464 | B73: 0
...

Sheet XWL
A2: Color Source PAR Deep Blue | B2: 43656
B4: Beam Angle | C4: Field Angle
A5: Horizontal | B5: 61.9 | C5: 82.9
F6: Lens Efficiency | G6: Power Consump (Watts) | H6: Efficacy (lm/W)
A7: Mode | B7: Accessory Lens | C7: Candela | D7: Field Lumens | E7: Beam Lumens
A8: Full ON / RGB | B8: XWL | C8: ='No Lens'!C8*XWL!K8 -> 12728.228 | D8: ='No Lens'!D8*XWL!L8 -> 2785.4274 | E8: ='No Lens'!E8*XWL!M8 -> 1457.3684 | F8: =D8/'No Lens'!D8 -> 1.0037576 | G8: 101.2 | H8: =D8/G8 -> 27.523986 | K8: 0.24911883 | L8: 1.0037576 | M8: 0.83660644
A9: 3200K / RGB | B9: XWL | C9: =C8*0.96990745 -> 12345.203 | D9: =D8*0.96990745 -> 2701.6068 | E9: =E8*0.96990745 -> 1413.5125 | F9: =D9/'No Lens'!D9 -> 0.97460563 | G9: 72.3 | H9: =D9/G9 -> 37.366623
A10: 5600K / RGB | B10: XWL | C10: =C8*0.955419195 -> 12160.794 | D10: =D8*0.955419195 -> 2661.2508 | E10: =E8*0.955419195 -> 1392.3978 | F10: =D10/'No Lens'!D10 -> 0.97732311 | G10: 101.6 | H10: =D10/G10 -> 26.193414
A11: Red / RGB | B11: XWL | C11: =C8*0.204137629 -> 2598.3103 | D11: =D8*0.204137629 -> 568.61055 | E11: =E8*0.204137629 -> 297.50373 | F11: =D11/'No Lens'!D11 -> 0.96702475 | G11: 29.1 | H11: =D11/G11 -> 19.539881
A12: Green / RGB | B12: XWL | C12: =C8*0.355680917 -> 4527.1879 | D12: =D8*0.355680917 -> 990.72338 | E12: =E8*0.355680917 -> 518.35814 | F12: =D12/'No Lens'!D12 -> 0.98383653 | G12: 34.3 | H12: =D12/G12 -> 28.884064
A13: Blue / RGB | B13: XWL | C13: =C8*0.041302273 -> 525.70476 | D13: =D8*0.041302273 -> 115.04448 | E13: =E8*0.041302273 -> 60.192628 | F13: =D13/'No Lens'!D13 -> 0.96676037 | G13: 32.2 | H13: =D13/G13 -> 3.5728101
A14: Full ON / Direct | B14: XWL | C14: =C8*1.043529672 -> 13282.284 | D14: =D8*1.043529672 -> 2906.6762 | E14: =E8*1.043529672 -> 1520.8072 | F14: =D14/'No Lens'!D14 -> 0.97604976 | G14: 108 | H14: =D14/G14 -> 26.913668
A15: Red / Direct | B15: XWL | C15: =C8*0.203860398 -> 2594.7817 | D15: =D8*0.203860398 -> 567.83834 | E15: =E8*0.203860398 -> 297.09971 | F15: =D15/'No Lens'!D15 -> 0.96900741 | G15: 28.8 | H15: =D15/G15 -> 19.716609
A16: Lime / Direct | B16: XWL | C16: =C8*0.454361902 -> 5783.222 | D16: =D8*0.454361902 -> 1265.5921 | E16: =E8*0.454361902 -> 662.17269 | F16: =D16/'No Lens'!D16 -> 0.97653712 | G16: 22.2 | H16: =D16/G16 -> 57.008653
A17: Green / Direct | B17: XWL | C17: =C8*0.357567841 -> 4551.2051 | D17: =D8*0.357567841 -> 995.97927 | E17: =E8*0.357567841 -> 521.10808 | F17: =D17/'No Lens'!D17 -> 0.98611809 | G17: 34.2 | H17: =D17/G17 -> 29.122201
A18: Blue / Direct | B18: XWL | C18: =C8*0.037144801 -> 472.78751 | D18: =D8*0.037144801 -> 103.46415 | E18: =E8*0.037144801 -> 54.13366 | F18: =D18/'No Lens'!D18 -> 0.96695465 | G18: 32.3 | H18: =D18/G18 -> 3.2032244
B20: For Field diameter at any distance, multiply distance by | F20: =2*TAN(C5*3.1415926535/360) -> 1.7663415
B22: For Beam diameter at any distance, multiply distance by | F22: =2*TAN(B5*3.1415926535/360) -> 1.199347
G23: Dist for 1.0 fc
